<?xml version="1.0" ?>
<!-- =================================================================================== -->
<!-- |    This document was autogenerated by xacro from /workspace/ros2_ws/src/steve_description/urdf/steve.urdf.xacro | -->
<!-- |    EDITING THIS FILE BY HAND IS NOT RECOMMENDED                                 | -->
<!-- =================================================================================== -->
<robot name="steve_robot" xmlns:controller="http://playerstage.sourceforge.net/gazebo/xmlschema/#controller" xmlns:interface="http://playerstage.sourceforge.net/gazebo/xmlschema/#interface" xmlns:sensor="http://playerstage.sourceforge.net/gazebo/xmlschema/#sensor">
  <!-- ************************************************************************ -->
  <!-- ========================= MMO_700 ====================================== -->
  <!-- ************************************************************************ -->
  <!-- =================== MMO_700 BODY =================== -->
  <link name="base_link">
    <inertial>
      <mass value="200"/>
      <origin xyz="0 0 0"/>
      <inertia ixx="5.652232699207" ixy="0.009719934438" ixz="1.293988226423" iyy="5.669473158652" iyz="0.007379583694" izz="5.683196351726"/>
    </inertial>
    <visual>
      <origin rpy="0 0 -1.571" xyz="0.0 0.0 0.0"/>
      <geometry>
        <mesh filename="package://steve_description/meshes/mmo_700/MPO-700-BODY.dae" scale="0.001 0.001 0.001"/>
      </geometry>
    </visual>
    <collision>
      <origin rpy="0 0 -1.571" xyz="0. 0. 0."/>
      <geometry>
        <mesh filename="package://steve_description/meshes/mmo_700/MPO-700-BODY.dae" scale="0.001 0.001 0.001"/>
      </geometry>
    </collision>
  </link>
  <!-- =================== FRONT LEFT CASTER =================== -->
  <link name="mmo_700_caster_front_left_link">
    <inertial>
      <mass value="9"/>
      <origin rpy="0 0 0" xyz="0 0 0"/>
      <inertia ixx="0.00044332" ixy="0" ixz="0" iyy="0.00044332" iyz="0" izz="0.00072"/>
    </inertial>
    <visual>
      <origin rpy="0 0 0" xyz="0 0 0.10"/>
      <geometry>
        <mesh filename="package://steve_description/meshes/mmo_700/MPO-700-HEAD.dae" scale="0.001 0.001 0.001"/>
      </geometry>
    </visual>
    <collision>
      <origin rpy="0 0 0" xyz="0 0 0.10"/>
      <geometry>
        <mesh filename="package://steve_description/meshes/mmo_700/MPO-700-HEAD.dae" scale="0.001 0.001 0.001"/>
      </geometry>
    </collision>
  </link>
  <joint name="mmo_700_caster_front_left_joint" type="continuous">
    <origin rpy="3.14 0 -1.57" xyz="0.24 0.18 0.27"/>
    <axis xyz="0 0 -1"/>
    <limit effort="1000.0" lower="-1e+16" upper="1e+16" velocity="3.5"/>
    <joint_properties damping="1" friction="1"/>
    <parent link="base_link"/>
    <child link="mmo_700_caster_front_left_link"/>
  </joint>
  <!-- Transmission-->
  <transmission name="mmo_700_caster_front_left_transmission">
    <type>transmission_interface/SimpleTransmission</type>
    <joint name="mmo_700_caster_front_left_joint">
      <hardwareInterface>hardware_interface/PositionJointInterface</hardwareInterface>
    </joint>
    <actuator name="mmo_700_caster_front_left_motor">
      <mechanicalReduction>1</mechanicalReduction>
    </actuator>
  </transmission>
  <!-- =================== FRONT RIGHT CASTER =================== -->
  <link name="mmo_700_caster_front_right_link">
    <inertial>
      <mass value="9"/>
      <origin rpy="0 0 0" xyz="0 0 0."/>
      <inertia ixx="0.00044332" ixy="0" ixz="0" iyy="0.00044332" iyz="0" izz="0.00072"/>
    </inertial>
    <visual>
      <origin rpy="0 0 0" xyz="0 0 0.10"/>
      <geometry>
        <mesh filename="package://steve_description/meshes/mmo_700/MPO-700-HEAD.dae" scale="0.001 0.001 0.001"/>
      </geometry>
    </visual>
    <collision>
      <origin rpy="0 0 0" xyz="0 0 0.10"/>
      <geometry>
        <mesh filename="package://steve_description/meshes/mmo_700/MPO-700-HEAD.dae" scale="0.001 0.001 0.001"/>
      </geometry>
    </collision>
  </link>
  <joint name="mmo_700_caster_front_right_joint" type="continuous">
    <origin rpy="3.14 0 1.57" xyz="0.24 -0.18 0.27"/>
    <axis xyz="0 0 -1"/>
    <limit effort="1000.0" lower="-1e+16" upper="1e+16" velocity="3.5"/>
    <joint_properties damping="1" friction="1"/>
    <parent link="base_link"/>
    <child link="mmo_700_caster_front_right_link"/>
  </joint>
  <!-- Transmission-->
  <transmission name="mmo_700_caster_front_right_transmission">
    <type>transmission_interface/SimpleTransmission</type>
    <joint name="mmo_700_caster_front_right_joint">
      <hardwareInterface>hardware_interface/PositionJointInterface</hardwareInterface>
    </joint>
    <actuator name="mmo_700_caster_front_right_motor">
      <mechanicalReduction>1</mechanicalReduction>
    </actuator>
  </transmission>
  <!-- =================== REAR LEFT CASTER =================== -->
  <link name="mmo_700_caster_back_left_link">
    <inertial>
      <mass value="9"/>
      <origin rpy="0 0 0" xyz="0 0 0."/>
      <inertia ixx="0.00044332" ixy="0" ixz="0" iyy="0.00044332" iyz="0" izz="0.00072"/>
    </inertial>
    <visual>
      <origin rpy="0 0 0" xyz="0 0 0.10"/>
      <geometry>
        <mesh filename="package://steve_description/meshes/mmo_700/MPO-700-HEAD.dae" scale="0.001 0.001 0.001"/>
      </geometry>
    </visual>
    <collision>
      <origin rpy="0 0 0" xyz="0 0 0.10"/>
      <geometry>
        <mesh filename="package://steve_description/meshes/mmo_700/MPO-700-HEAD.dae" scale="0.001 0.001 0.001"/>
      </geometry>
    </collision>
  </link>
  <joint name="mmo_700_caster_back_left_joint" type="continuous">
    <origin rpy="3.14 0 -1.57" xyz="-0.24 0.18 0.27"/>
    <axis xyz="0 0 -1"/>
    <limit effort="1000.0" lower="-1e+16" upper="1e+16" velocity="3.5"/>
    <joint_properties damping="1" friction="1"/>
    <parent link="base_link"/>
    <child link="mmo_700_caster_back_left_link"/>
  </joint>
  <!-- Transmission-->
  <transmission name="mmo_700_caster_back_left_transmission">
    <type>transmission_interface/SimpleTransmission</type>
    <joint name="mmo_700_caster_back_left_joint">
      <hardwareInterface>hardware_interface/PositionJointInterface</hardwareInterface>
    </joint>
    <actuator name="mmo_700_caster_back_left_motor">
      <mechanicalReduction>1</mechanicalReduction>
    </actuator>
  </transmission>
  <!-- =================== REAR RIGHT CASTER =================== -->
  <link name="mmo_700_caster_back_right_link">
    <inertial>
      <mass value="9"/>
      <origin rpy="0 0 0" xyz="0 0 0"/>
      <inertia ixx="0.00044332" ixy="0" ixz="0" iyy="0.00044332" iyz="0" izz="0.00072"/>
    </inertial>
    <visual>
      <origin rpy="0 0 0" xyz="0 0 0.10"/>
      <geometry>
        <mesh filename="package://steve_description/meshes/mmo_700/MPO-700-HEAD.dae" scale="0.001 0.001 0.001"/>
      </geometry>
    </visual>
    <collision>
      <origin rpy="0 0 0" xyz="0 0 0.10"/>
      <geometry>
        <mesh filename="package://steve_description/meshes/mmo_700/MPO-700-HEAD.dae" scale="0.001 0.001 0.001"/>
      </geometry>
    </collision>
  </link>
  <joint name="mmo_700_caster_back_right_joint" type="continuous">
    <origin rpy="3.14 0 1.57" xyz="-0.24 -0.18 0.27"/>
    <axis xyz="0 0 -1"/>
    <limit effort="1000.0" lower="-1e+16" upper="1e+16" velocity="3.5"/>
    <joint_properties damping="1" friction="1"/>
    <parent link="base_link"/>
    <child link="mmo_700_caster_back_right_link"/>
  </joint>
  <!-- Transmission-->
  <transmission name="mmo_700_caster_back_right_transmission">
    <type>transmission_interface/SimpleTransmission</type>
    <joint name="mmo_700_caster_back_right_joint">
      <hardwareInterface>hardware_interface/PositionJointInterface</hardwareInterface>
    </joint>
    <actuator name="mmo_700_caster_back_right_motor">
      <mechanicalReduction>1</mechanicalReduction>
    </actuator>
  </transmission>
  <!-- =================== MMO_700 WHEEL =================== -->
  <link name="mmo_700_wheel_front_left_link" type="wheel">
    <inertial>
      <mass value="5.9"/>
      <origin rpy="0 0 0" xyz="0 0 0"/>
      <inertia ixx="0.04" ixy="0.0007" ixz="0.0" iyy="0.02" iyz="0.004" izz="0.05"/>
    </inertial>
    <visual>
      <origin rpy="0 0 0" xyz="0 0 0"/>
      <geometry>
        <mesh filename="package://steve_description/meshes/mmo_700/MPO-700-WHEEL.dae" scale="0.001 0.001 0.001"/>
      </geometry>
    </visual>
    <collision>
      <origin rpy="0 0 0" xyz="0 0 0"/>
      <geometry>
        <mesh filename="package://steve_description/meshes/mmo_700/MPO-700-WHEEL.dae" scale="0.001 0.001 0.001"/>
      </geometry>
    </collision>
  </link>
  <joint name="mmo_700_wheel_front_left_joint" type="continuous">
    <origin rpy="0 0 0" xyz="-0.05 0. 0.18"/>
    <limit effort="1000.0" lower="-1e+16" upper="1e+16" velocity="3.5"/>
    <axis xyz="1 0 0"/>
    <parent link="mmo_700_caster_front_left_link"/>
    <child link="mmo_700_wheel_front_left_link"/>
  </joint>
  <gazebo reference="mmo_700_wheel_front_left_link">
    <mu1 value="0.05"/>
    <mu2 value="0.05"/>
    <kp value="100000.0"/>
    <kd value="10.0"/>
  </gazebo>
  <!-- Add transmission for the wheel joint -->
  <transmission name="mmo_700_wheel_front_left_transmission">
    <type>transmission_interface/SimpleTransmission</type>
    <joint name="mmo_700_wheel_front_left_joint">
      <hardwareInterface>hardware_interface/VelocityJointInterface</hardwareInterface>
    </joint>
    <actuator name="mmo_700_wheel_front_left_motor">
      <mechanicalReduction>1</mechanicalReduction>
    </actuator>
  </transmission>
  <!-- =================== MMO_700 WHEEL =================== -->
  <link name="mmo_700_wheel_front_right_link" type="wheel">
    <inertial>
      <mass value="5.9"/>
      <origin rpy="0 0 0" xyz="0 0 0"/>
      <inertia ixx="0.04" ixy="0.0007" ixz="0.0" iyy="0.02" iyz="0.004" izz="0.05"/>
    </inertial>
    <visual>
      <origin rpy="0 0 0" xyz="0 0 0"/>
      <geometry>
        <mesh filename="package://steve_description/meshes/mmo_700/MPO-700-WHEEL.dae" scale="0.001 0.001 0.001"/>
      </geometry>
    </visual>
    <collision>
      <origin rpy="0 0 0" xyz="0 0 0"/>
      <geometry>
        <mesh filename="package://steve_description/meshes/mmo_700/MPO-700-WHEEL.dae" scale="0.001 0.001 0.001"/>
      </geometry>
    </collision>
  </link>
  <joint name="mmo_700_wheel_front_right_joint" type="continuous">
    <origin rpy="0 0 0" xyz="-0.05 0. 0.18"/>
    <limit effort="1000.0" lower="-1e+16" upper="1e+16" velocity="3.5"/>
    <axis xyz="1 0 0"/>
    <parent link="mmo_700_caster_front_right_link"/>
    <child link="mmo_700_wheel_front_right_link"/>
  </joint>
  <gazebo reference="mmo_700_wheel_front_right_link">
    <mu1 value="0.05"/>
    <mu2 value="0.05"/>
    <kp value="100000.0"/>
    <kd value="10.0"/>
  </gazebo>
  <!-- Add transmission for the wheel joint -->
  <transmission name="mmo_700_wheel_front_right_transmission">
    <type>transmission_interface/SimpleTransmission</type>
    <joint name="mmo_700_wheel_front_right_joint">
      <hardwareInterface>hardware_interface/VelocityJointInterface</hardwareInterface>
    </joint>
    <actuator name="mmo_700_wheel_front_right_motor">
      <mechanicalReduction>1</mechanicalReduction>
    </actuator>
  </transmission>
  <!-- =================== MMO_700 WHEEL =================== -->
  <link name="mmo_700_wheel_back_left_link" type="wheel">
    <inertial>
      <mass value="5.9"/>
      <origin rpy="0 0 0" xyz="0 0 0"/>
      <inertia ixx="0.04" ixy="0.0007" ixz="0.0" iyy="0.02" iyz="0.004" izz="0.05"/>
    </inertial>
    <visual>
      <origin rpy="0 0 0" xyz="0 0 0"/>
      <geometry>
        <mesh filename="package://steve_description/meshes/mmo_700/MPO-700-WHEEL.dae" scale="0.001 0.001 0.001"/>
      </geometry>
    </visual>
    <collision>
      <origin rpy="0 0 0" xyz="0 0 0"/>
      <geometry>
        <mesh filename="package://steve_description/meshes/mmo_700/MPO-700-WHEEL.dae" scale="0.001 0.001 0.001"/>
      </geometry>
    </collision>
  </link>
  <joint name="mmo_700_wheel_back_left_joint" type="continuous">
    <origin rpy="0 0 0" xyz="-0.05 0. 0.18"/>
    <limit effort="1000.0" lower="-1e+16" upper="1e+16" velocity="3.5"/>
    <axis xyz="1 0 0"/>
    <parent link="mmo_700_caster_back_left_link"/>
    <child link="mmo_700_wheel_back_left_link"/>
  </joint>
  <gazebo reference="mmo_700_wheel_back_left_link">
    <mu1 value="0.05"/>
    <mu2 value="0.05"/>
    <kp value="100000.0"/>
    <kd value="10.0"/>
  </gazebo>
  <!-- Add transmission for the wheel joint -->
  <transmission name="mmo_700_wheel_back_left_transmission">
    <type>transmission_interface/SimpleTransmission</type>
    <joint name="mmo_700_wheel_back_left_joint">
      <hardwareInterface>hardware_interface/VelocityJointInterface</hardwareInterface>
    </joint>
    <actuator name="mmo_700_wheel_back_left_motor">
      <mechanicalReduction>1</mechanicalReduction>
    </actuator>
  </transmission>
  <!-- =================== MMO_700 WHEEL =================== -->
  <link name="mmo_700_wheel_back_right_link" type="wheel">
    <inertial>
      <mass value="5.9"/>
      <origin rpy="0 0 0" xyz="0 0 0"/>
      <inertia ixx="0.04" ixy="0.0007" ixz="0.0" iyy="0.02" iyz="0.004" izz="0.05"/>
    </inertial>
    <visual>
      <origin rpy="0 0 0" xyz="0 0 0"/>
      <geometry>
        <mesh filename="package://steve_description/meshes/mmo_700/MPO-700-WHEEL.dae" scale="0.001 0.001 0.001"/>
      </geometry>
    </visual>
    <collision>
      <origin rpy="0 0 0" xyz="0 0 0"/>
      <geometry>
        <mesh filename="package://steve_description/meshes/mmo_700/MPO-700-WHEEL.dae" scale="0.001 0.001 0.001"/>
      </geometry>
    </collision>
  </link>
  <joint name="mmo_700_wheel_back_right_joint" type="continuous">
    <origin rpy="0 0 0" xyz="-0.05 0. 0.18"/>
    <limit effort="1000.0" lower="-1e+16" upper="1e+16" velocity="3.5"/>
    <axis xyz="1 0 0"/>
    <parent link="mmo_700_caster_back_right_link"/>
    <child link="mmo_700_wheel_back_right_link"/>
  </joint>
  <gazebo reference="mmo_700_wheel_back_right_link">
    <mu1 value="0.05"/>
    <mu2 value="0.05"/>
    <kp value="100000.0"/>
    <kd value="10.0"/>
  </gazebo>
  <!-- Add transmission for the wheel joint -->
  <transmission name="mmo_700_wheel_back_right_transmission">
    <type>transmission_interface/SimpleTransmission</type>
    <joint name="mmo_700_wheel_back_right_joint">
      <hardwareInterface>hardware_interface/VelocityJointInterface</hardwareInterface>
    </joint>
    <actuator name="mmo_700_wheel_back_right_motor">
      <mechanicalReduction>1</mechanicalReduction>
    </actuator>
  </transmission>
  <!-- ================== MMO_700 CABINET ================== -->
  <link name="cabinet_link">
    <inertial>
      <mass value="2"/>
      <origin rpy="0 0 0" xyz="0 0 0"/>
      <inertia ixx="0.457072" ixy="0.0" ixz="0.0" iyy="0.23616" iyz="0.0" izz="0.686"/>
    </inertial>
    <visual>
      <origin rpy="0 0 -1.5708" xyz="0 0 0"/>
      <geometry>
        <mesh filename="package://steve_description/meshes/mmo_700/cabin.dae" scale="0.001 0.001 0.001"/>
      </geometry>
    </visual>
    <collision>
      <origin rpy="0 0 -1.5708" xyz="0 0 0"/>
      <geometry>
        <mesh filename="package://steve_description/meshes/mmo_700/cabin.dae" scale="0.001 0.001 0.001"/>
      </geometry>
    </collision>
  </link>
  <joint name="cabinet_joint" type="fixed">
    <origin rpy="0 0 0" xyz="0.072 0 0.35"/>
    <joint_properties damping="1" friction="1"/>
    <parent link="base_link"/>
    <child link="cabinet_link"/>
  </joint>
  <!-- ====================== IMU ====================== -->
  <link name="imu_link">
    <inertial>
      <mass value="0.001"/>
      <origin rpy="0 0 0" xyz="0 0 0"/>
      <inertia ixx="0.0001" ixy="0" ixz="0" iyy="0.000001" iyz="0" izz="0.0001"/>
    </inertial>
  </link>
  <joint name="imu_joint" type="fixed">
    <axis xyz="0 1 0"/>
    <origin rpy="0 0 3.14" xyz="0.100 0 0.300"/>
    <parent link="base_link"/>
    <child link="imu_link"/>
  </joint>
  <!-- =================== MICRO SCAN =================== -->
  <link name="lidar_1_link" type="laser">
    <inertial>
      <mass value="0.0001"/>
      <origin rpy="0 0 0" xyz="0 0 0"/>
      <inertia ixx="0.0001" ixy="0" ixz="0" iyy="0.000001" iyz="0" izz="0.0001"/>
    </inertial>
    <visual>
      <origin rpy="1.57 0 0" xyz="0 0 -0.06"/>
      <geometry>
        <mesh filename="package://steve_description/meshes/mmo_700/SICK-MICROSCAN3.dae" scale="0.001 0.001 0.001"/>
      </geometry>
    </visual>
    <collision>
      <origin rpy="1.57 0 0" xyz="0 0 -0.06"/>
      <geometry>
        <mesh filename="package://steve_description/meshes/mmo_700/SICK-MICROSCAN3.dae" scale="0.001 0.001 0.001"/>
      </geometry>
    </collision>
  </link>
  <joint name="lidar_1_joint" type="fixed">
    <axis xyz="0 1 0"/>
    <origin rpy="3.14 0 0.79" xyz="0.338 0.288 0.223"/>
    <parent link="base_link"/>
    <child link="lidar_1_link"/>
  </joint>
  <!-- =================== MICRO SCAN =================== -->
  <link name="lidar_2_link" type="laser">
    <inertial>
      <mass value="0.0001"/>
      <origin rpy="0 0 0" xyz="0 0 0"/>
      <inertia ixx="0.0001" ixy="0" ixz="0" iyy="0.000001" iyz="0" izz="0.0001"/>
    </inertial>
    <visual>
      <origin rpy="1.57 0 0" xyz="0 0 -0.06"/>
      <geometry>
        <mesh filename="package://steve_description/meshes/mmo_700/SICK-MICROSCAN3.dae" scale="0.001 0.001 0.001"/>
      </geometry>
    </visual>
    <collision>
      <origin rpy="1.57 0 0" xyz="0 0 -0.06"/>
      <geometry>
        <mesh filename="package://steve_description/meshes/mmo_700/SICK-MICROSCAN3.dae" scale="0.001 0.001 0.001"/>
      </geometry>
    </collision>
  </link>
  <joint name="lidar_2_joint" type="fixed">
    <axis xyz="0 1 0"/>
    <origin rpy="3.14 0 3.93" xyz="-0.338 -0.288 0.223"/>
    <parent link="base_link"/>
    <child link="lidar_2_link"/>
  </joint>
  <!-- ***************************************************************************** -->
  <!-- ===================================== UR5E ================================== -->
  <!-- ***************************************************************************** -->
  <!-- ur5e links -->
  <link name="ur5e_base_link"/>
  <link name="ur5e_base_link_inertia">
    <visual>
      <origin rpy="0 0 3.141592653589793" xyz="0 0 0"/>
      <geometry>
        <mesh filename="package://steve_description/meshes/ur5e/visual/base.dae"/>
      </geometry>
    </visual>
    <collision>
      <origin rpy="0 0 3.141592653589793" xyz="0 0 0"/>
      <geometry>
        <mesh filename="package://steve_description/meshes/ur5e/collision/base.stl"/>
      </geometry>
    </collision>
    <inertial>
      <mass value="4.0"/>
      <origin rpy="0 0 0" xyz="0 0 0"/>
      <inertia ixx="0.00443333156" ixy="0.0" ixz="0.0" iyy="0.00443333156" iyz="0.0" izz="0.0072"/>
    </inertial>
  </link>
  <link name="ur5e_shoulder_link">
    <visual>
      <origin rpy="0 0 3.141592653589793" xyz="0 0 0"/>
      <geometry>
        <mesh filename="package://steve_description/meshes/ur5e/visual/shoulder.dae"/>
      </geometry>
    </visual>
    <collision>
      <origin rpy="0 0 3.141592653589793" xyz="0 0 0"/>
      <geometry>
        <mesh filename="package://steve_description/meshes/ur5e/collision/shoulder.stl"/>
      </geometry>
    </collision>
    <inertial>
      <mass value="3.761"/>
      <origin rpy="0 0 0" xyz="0.0 -0.00193 -0.02561"/>
      <inertia ixx="0.010267499999999999" ixy="0" ixz="0" iyy="0.010267499999999999" iyz="0" izz="0.00666"/>
    </inertial>
  </link>
  <link name="ur5e_upper_arm_link">
    <visual>
      <origin rpy="1.5707963267948966 0 -1.5707963267948966" xyz="0 0 0.138"/>
      <geometry>
        <mesh filename="package://steve_description/meshes/ur5e/visual/upperarm.dae"/>
      </geometry>
    </visual>
    <collision>
      <origin rpy="1.5707963267948966 0 -1.5707963267948966" xyz="0 0 0.138"/>
      <geometry>
        <mesh filename="package://steve_description/meshes/ur5e/collision/upperarm.stl"/>
      </geometry>
    </collision>
    <inertial>
      <mass value="8.058"/>
      <origin rpy="0 1.570796326794897 0" xyz="-0.2125 0.0 0.11336"/>
      <inertia ixx="0.13388583541666665" ixy="0" ixz="0" iyy="0.13388583541666665" iyz="0" izz="0.0151074"/>
    </inertial>
  </link>
  <link name="ur5e_forearm_link">
    <visual>
      <origin rpy="1.5707963267948966 0 -1.5707963267948966" xyz="0 0 0.007"/>
      <geometry>
        <mesh filename="package://steve_description/meshes/ur5e/visual/forearm.dae"/>
      </geometry>
    </visual>
    <collision>
      <origin rpy="1.5707963267948966 0 -1.5707963267948966" xyz="0 0 0.007"/>
      <geometry>
        <mesh filename="package://steve_description/meshes/ur5e/collision/forearm.stl"/>
      </geometry>
    </collision>
    <inertial>
      <mass value="2.846"/>
      <origin rpy="0 1.570796326794897 0" xyz="-0.2422 0.0 0.0265"/>
      <inertia ixx="0.03120936758333333" ixy="0" ixz="0" iyy="0.03120936758333333" iyz="0" izz="0.004095"/>
    </inertial>
  </link>
  <link name="ur5e_wrist_1_link">
    <visual>
      <origin rpy="1.5707963267948966 0 0" xyz="0 0 -0.127"/>
      <geometry>
        <mesh filename="package://steve_description/meshes/ur5e/visual/wrist1.dae"/>
      </geometry>
    </visual>
    <collision>
      <origin rpy="1.5707963267948966 0 0" xyz="0 0 -0.127"/>
      <geometry>
        <mesh filename="package://steve_description/meshes/ur5e/collision/wrist1.stl"/>
      </geometry>
    </collision>
    <inertial>
      <mass value="1.37"/>
      <origin rpy="0 0 0" xyz="0.0 -0.01634 -0.0018"/>
      <inertia ixx="0.0025599" ixy="0" ixz="0" iyy="0.0025599" iyz="0" izz="0.0021942"/>
    </inertial>
  </link>
  <link name="ur5e_wrist_2_link">
    <visual>
      <origin rpy="0 0 0" xyz="0 0 -0.0997"/>
      <geometry>
        <mesh filename="package://steve_description/meshes/ur5e/visual/wrist2.dae"/>
      </geometry>
    </visual>
    <collision>
      <origin rpy="0 0 0" xyz="0 0 -0.0997"/>
      <geometry>
        <mesh filename="package://steve_description/meshes/ur5e/collision/wrist2.stl"/>
      </geometry>
    </collision>
    <inertial>
      <mass value="1.3"/>
      <origin rpy="0 0 0" xyz="0.0 0.01634 -0.0018"/>
      <inertia ixx="0.0025599" ixy="0" ixz="0" iyy="0.0025599" iyz="0" izz="0.0021942"/>
    </inertial>
  </link>
  <link name="ur5e_wrist_3_link">
    <visual>
      <origin rpy="1.5707963267948966 0 0" xyz="0 0 -0.0989"/>
      <geometry>
        <mesh filename="package://steve_description/meshes/ur5e/visual/wrist3.dae"/>
      </geometry>
    </visual>
    <collision>
      <origin rpy="1.5707963267948966 0 0" xyz="0 0 -0.0989"/>
      <geometry>
        <mesh filename="package://steve_description/meshes/ur5e/collision/wrist3.stl"/>
      </geometry>
    </collision>
    <inertial>
      <mass value="0.365"/>
      <origin rpy="0 0 0" xyz="0.0 0.0 -0.001159"/>
      <inertia ixx="9.890414008333333e-05" ixy="0" ixz="0" iyy="9.890414008333333e-05" iyz="0" izz="0.0001321171875"/>
    </inertial>
  </link>
  <!-- ur5e joints -->
  <joint name="ur5e_base_joint" type="fixed">
    <origin rpy="0.0 0.0 0.0" xyz="0.133 0.0 0.416"/>
    <!-- <origin rpy="3.141592653589793/2 3.141592653589793/2 0" xyz="0 0 0"/> -->
    <parent link="cabinet_link"/>
    <child link="ur5e_base_link"/>
  </joint>
  <joint name="ur5e_base_link-base_link_inertia" type="fixed">
    <parent link="ur5e_base_link"/>
    <child link="ur5e_base_link_inertia"/>
    <!-- 'base_link' is REP-103 aligned (so X+ forward), while the internal
                frames of the robot/controller have X+ pointing backwards.
                Use the joint between 'base_link' and 'base_link_inertia' (a dummy
                link/frame) to introduce the necessary rotation over Z (of pi rad).
            -->
    <origin rpy="0 0 3.141592653589793" xyz="0 0 0"/>
  </joint>
  <joint name="ur5e_shoulder_pan_joint" type="revolute">
    <parent link="ur5e_base_link_inertia"/>
    <child link="ur5e_shoulder_link"/>
    <origin rpy="0 0 0" xyz="0 0 0.1625"/>
    <axis xyz="0 0 1"/>
    <limit effort="150.0" lower="-6.283185307179586" upper="6.283185307179586" velocity="3.141592653589793"/>
    <dynamics damping="0" friction="0"/>
  </joint>
  <joint name="ur5e_shoulder_lift_joint" type="revolute">
    <parent link="ur5e_shoulder_link"/>
    <child link="ur5e_upper_arm_link"/>
    <origin rpy="1.570796327 0 0" xyz="0 0 0"/>
    <axis xyz="0 0 1"/>
    <limit effort="150.0" lower="-6.283185307179586" upper="6.283185307179586" velocity="3.141592653589793"/>
    <dynamics damping="0" friction="0"/>
  </joint>
  <joint name="ur5e_elbow_joint" type="revolute">
    <parent link="ur5e_upper_arm_link"/>
    <child link="ur5e_forearm_link"/>
    <origin rpy="0 0 0" xyz="-0.425 0 0"/>
    <axis xyz="0 0 1"/>
    <limit effort="150.0" lower="-3.141592653589793" upper="3.141592653589793" velocity="3.141592653589793"/>
    <dynamics damping="0" friction="0"/>
  </joint>
  <joint name="ur5e_wrist_1_joint" type="revolute">
    <parent link="ur5e_forearm_link"/>
    <child link="ur5e_wrist_1_link"/>
    <origin rpy="0 0 0" xyz="-0.3922 0 0.1333"/>
    <axis xyz="0 0 1"/>
    <limit effort="28.0" lower="-6.283185307179586" upper="6.283185307179586" velocity="3.141592653589793"/>
    <dynamics damping="0" friction="0"/>
  </joint>
  <joint name="ur5e_wrist_2_joint" type="revolute">
    <parent link="ur5e_wrist_1_link"/>
    <child link="ur5e_wrist_2_link"/>
    <origin rpy="1.570796327 0 0" xyz="0 -0.0997 -2.044881182297852e-11"/>
    <axis xyz="0 0 1"/>
    <limit effort="28.0" lower="-6.283185307179586" upper="6.283185307179586" velocity="3.141592653589793"/>
    <dynamics damping="0" friction="0"/>
  </joint>
  <joint name="ur5e_wrist_3_joint" type="revolute">
    <parent link="ur5e_wrist_2_link"/>
    <child link="ur5e_wrist_3_link"/>
    <origin rpy="1.570796326589793 3.141592653589793 3.141592653589793" xyz="0 0.0996 -2.042830148012698e-11"/>
    <axis xyz="0 0 1"/>
    <limit effort="28.0" lower="-6.283185307179586" upper="6.283185307179586" velocity="3.141592653589793"/>
    <dynamics damping="0" friction="0"/>
  </joint>
  <link name="ur5e_ft_frame"/>
  <joint name="ur5e_wrist_3_link-ft_frame" type="fixed">
    <parent link="ur5e_wrist_3_link"/>
    <child link="ur5e_ft_frame"/>
    <origin rpy="3.141592653589793 0 0" xyz="0 0 0"/>
  </joint>
  <!-- ROS-Industrial 'base' frame - base_link to UR 'Base' Coordinates transform -->
  <link name="ur5e_base"/>
  <joint name="ur5e_base_link-base_fixed_joint" type="fixed">
    <!-- Note the rotation over Z of pi radians - as base_link is REP-103
                aligned (i.e., has X+ forward, Y+ left and Z+ up), this is needed
                to correctly align 'base' with the 'Base' coordinate system of
                the UR controller.
            -->
    <origin rpy="0 0 3.141592653589793" xyz="0 0 0"/>
    <parent link="ur5e_base_link"/>
    <child link="ur5e_base"/>
  </joint>
  <!-- ROS-Industrial 'flange' frame - attachment point for EEF models -->
  <link name="ur5e_flange"/>
  <joint name="ur5e_wrist_3-flange" type="fixed">
    <parent link="ur5e_wrist_3_link"/>
    <child link="ur5e_flange"/>
    <origin rpy="0 -1.5707963267948966 -1.5707963267948966" xyz="0 0 0"/>
  </joint>
  <!-- ROS-Industrial 'tool0' frame - all-zeros tool frame -->
  <link name="ur5e_tool0"/>
  <joint name="ur5e_flange-tool0" type="fixed">
    <!-- default toolframe - X+ left, Y+ up, Z+ front -->
    <origin rpy="1.5707963267948966 0 1.5707963267948966" xyz="0 0 0"/>
    <parent link="ur5e_flange"/>
    <child link="ur5e_tool0"/>
  </joint>
  <!-- transmissions -->
  <transmission name="ur5e_shoulder_pan_transmission">
    <type>transmission_interface/SimpleTransmission</type>
    <joint name="ur5e_shoulder_pan_joint">
      <hardwareInterface>hardware_interface/VelocityJointInterface</hardwareInterface>
    </joint>
    <actuator name="ur5e_shoulder_pan_motor">
      <mechanicalReduction>1</mechanicalReduction>
    </actuator>
  </transmission>
  <transmission name="ur5e_shoulder_lift_transmission">
    <type>transmission_interface/SimpleTransmission</type>
    <joint name="ur5e_shoulder_lift_joint">
      <hardwareInterface>hardware_interface/VelocityJointInterface</hardwareInterface>
    </joint>
    <actuator name="ur5e_shoulder_lift_motor">
      <mechanicalReduction>1</mechanicalReduction>
    </actuator>
  </transmission>
  <transmission name="ur5e_elbow_transmission">
    <type>transmission_interface/SimpleTransmission</type>
    <joint name="ur5e_elbow_joint">
      <hardwareInterface>hardware_interface/VelocityJointInterface</hardwareInterface>
    </joint>
    <actuator name="ur5e_elbow_motor">
      <mechanicalReduction>1</mechanicalReduction>
    </actuator>
  </transmission>
  <transmission name="ur5e_wrist_1_transmission">
    <type>transmission_interface/SimpleTransmission</type>
    <joint name="ur5e_wrist_1_joint">
      <hardwareInterface>hardware_interface/VelocityJointInterface</hardwareInterface>
    </joint>
    <actuator name="ur5e_wrist_1_motor">
      <mechanicalReduction>1</mechanicalReduction>
    </actuator>
  </transmission>
  <transmission name="ur5e_wrist_2_transmission">
    <type>transmission_interface/SimpleTransmission</type>
    <joint name="ur5e_wrist_2_joint">
      <hardwareInterface>hardware_interface/VelocityJointInterface</hardwareInterface>
    </joint>
    <actuator name="ur5e_wrist_2_motor">
      <mechanicalReduction>1</mechanicalReduction>
    </actuator>
  </transmission>
  <transmission name="ur5e_wrist_3_transmission">
    <type>transmission_interface/SimpleTransmission</type>
    <joint name="ur5e_wrist_3_joint">
      <hardwareInterface>hardware_interface/VelocityJointInterface</hardwareInterface>
    </joint>
    <actuator name="ur5e_wrist_3_motor">
      <mechanicalReduction>1</mechanicalReduction>
    </actuator>
  </transmission>
  <!-- ****************************************************************** -->
  <!-- ====================== ABILITY HAND ============================== -->
  <!-- ****************************************************************** -->
  <joint name="ur5e_tool0_hand_joint" type="fixed">
    <parent link="ur5e_tool0"/>
    <child link="hand_mount"/>
    <origin rpy="1.5707963267948966 0.0 3.141592653589793" xyz="0.0 0.0 0.0"/>
  </joint>
  <!-- define materials -->
  <material name="white">
    <color rgba="1 1 1 1"/>
  </material>
  <material name="black">
    <color rgba="0.2 0.2 0.2 1"/>
  </material>
  <link name="hand_mount">
    <visual>
      <origin rpy="0 0 0" xyz="0 0 0"/>
      <geometry>
        <mesh filename="package://steve_description/meshes/ability_hand/Psyonic_UR5_Inline.STL" scale="0.001 0.001 0.001"/>
      </geometry>
      <material name="white"/>
    </visual>
    <collision>
      <origin rpy="0 0 0" xyz="0 0 0"/>
      <geometry>
        <mesh filename="package://steve_description/meshes/ability_hand/Psyonic_UR5_Inline_lowpoly.STL" scale="0.001 0.001 0.001"/>
      </geometry>
    </collision>
    <inertial>
      <mass value="0.2"/>
      <inertia ixx="1.0" ixy="0.0" ixz="0.0" iyy="1.0" iyz="0.0" izz="1.0"/>
    </inertial>
  </link>
  <joint name="hand_mount_joint" type="fixed">
    <parent link="hand_mount"/>
    <child link="hand_base"/>
    <origin rpy="-1.5707963267948966 0.0 0.0" xyz="0.0 0.02 0.0"/>
  </joint>
  <link name="hand_base">
    <visual name="wrist_mesh">
      <origin rpy="0 0 0" xyz="0 0 0"/>
      <geometry>
        <mesh filename="package://steve_description/meshes/ability_hand/wristmesh.STL"/>
      </geometry>
      <material name="black"/>
    </visual>
    <collision>
      <origin rpy="0 0 0" xyz="0 0 0"/>
      <geometry>
        <mesh filename="package://steve_description/meshes/ability_hand/wristmesh.STL"/>
      </geometry>
    </collision>
    <inertial>
      <mass value="0.2"/>
      <inertia ixx="1.0" ixy="0.0" ixz="0.0" iyy="1.0" iyz="0.0" izz="1.0"/>
    </inertial>
  </link>
  <joint name="wrist2thumb" type="fixed">
    <parent link="hand_base"/>
    <child link="thumb_base"/>
    <origin rpy="3.14148426 -0.08848813 -3.14036612" xyz="-24.0476665e-3 3.78124745e-3 32.32964923e-3"/>
  </joint>
  <link name="thumb_base">
    <inertial>
      <mass value="0.2"/>
      <inertia ixx="1.0" ixy="0.0" ixz="0.0" iyy="1.0" iyz="0.0" izz="1.0"/>
    </inertial>
    <visual name="palm_mesh">
      <origin rpy="0 0 0" xyz="0 0 0"/>
      <geometry>
        <mesh filename="package://steve_description/meshes/ability_hand/FB_palm_ref_MIR.STL"/>
      </geometry>
      <material name="black"/>
    </visual>
    <collision>
      <origin rpy="0 0 0" xyz="0 0 0"/>
      <geometry>
        <mesh filename="package://steve_description/meshes/ability_hand/FB_palm_ref_MIR.STL"/>
      </geometry>
    </collision>
  </link>
  <link name="index_L1">
    <inertial>
      <mass value="0.00635888"/>
      <inertia ixx="0.29766e-6" ixy="-0.06447133e-6" ixz="-0.00423315e-6" iyy="3.6947967e-6" iyz="0.00083028e-6" izz="3.8176336e-6"/>
      <origin rpy="0 0 0" xyz="22.41911e-3 -0.15798201e-3 -0.01319866e-3"/>
    </inertial>
    <visual name="index_mesh_1">
      <origin rpy="0 0 0" xyz="0 0 0"/>
      <geometry>
        <mesh filename="package://steve_description/meshes/ability_hand/idx-F1.STL"/>
      </geometry>
      <material name="black"/>
    </visual>
    <collision>
      <origin rpy="0 0 0" xyz="0 0 0"/>
      <geometry>
        <mesh filename="package://steve_description/meshes/ability_hand/idx-F1.STL"/>
      </geometry>
    </collision>
  </link>
  <link name="index_L2">
    <inertial>
      <mass value="0.00645"/>
      <inertia ixx="0.82671e-6" ixy="-1.08876e-6" ixz="-0.00037e-6" iyy="1.98028e-6" iyz="0.00081e-6" izz="2.64638e-6"/>
      <origin rpy="0 0 0" xyz="13.36818e-3 -8.75392e-3 -0.02886e-3"/>
    </inertial>
    <visual name="index_mesh_2">
      <origin rpy="0 0 0" xyz="0 0 0"/>
      <geometry>
        <mesh filename="package://steve_description/meshes/ability_hand/idx-F2-Lg-2.STL"/>
      </geometry>
      <material name="black"/>
    </visual>
    <collision>
      <origin rpy="0 0 0" xyz="0 0 0"/>
      <geometry>
        <mesh filename="package://steve_description/meshes/ability_hand/idx-F2-Lg-2.STL"/>
      </geometry>
    </collision>
  </link>
  <joint name="index_joint" type="revolute">
    <parent link="thumb_base"/>
    <child link="index_L1"/>
    <origin rpy=" -1.1595426535897932 1.284473 -1.0510016535897932 " xyz=" 9.49e-3 -13.04e-3 -62.95e-3 "/>
    <axis xyz="0 0 1"/>
    <limit effort="6.0" lower="0" upper="2.0943951" velocity="8.0677777442"/>
    <!-- angles in rad, efforts in N-m, velocity in rad/s -->
    <dynamics damping="0.001" friction="0.001"/>
    <!-- Friction coefficient is not from quantitative measurement -->
  </joint>
  <joint name="index_mimic_joint" type="revolute">
    <parent link="index_L1"/>
    <child link="index_L2"/>
    <origin rpy="0 0 0" xyz="38.472723e-3 3.257695e-3 0.000000e-3"/>
    <axis xyz="0 0 1"/>
    <limit effort="6.0" lower="0.0" upper="2.6586" velocity="8.0677777442"/>
    <!-- angles in rad, efforts in N-m, velocity in rad/s -->
    <dynamics damping="0.001" friction="0.001"/>
    <!-- Friction coefficient is not from quantitative measurement -->
    <mimic joint="index_joint" multiplier="1.05851325" offset="0.2"/>
  </joint>
  <link name="index_anchor"/>
  <joint name="idx_anchor" type="fixed">
    <parent link="index_L2"/>
    <child link="index_anchor"/>
    <origin rpy="0 0 0" xyz="31.5541e-3  -10.44e-3 0.14e-3"/>
  </joint>
  <link name="middle_L1">
    <inertial>
      <mass value="0.00635888"/>
      <inertia ixx="0.29766e-6" ixy="-0.06447133e-6" ixz="-0.00423315e-6" iyy="3.6947967e-6" iyz="0.00083028e-6" izz="3.8176336e-6"/>
      <origin rpy="0 0 0" xyz="22.41911e-3 -0.15798201e-3 -0.01319866e-3"/>
    </inertial>
    <visual name="middle_mesh_1">
      <origin rpy="0 0 0" xyz="0 0 0"/>
      <geometry>
        <mesh filename="package://steve_description/meshes/ability_hand/idx-F1.STL"/>
      </geometry>
      <material name="black"/>
    </visual>
    <collision>
      <origin rpy="0 0 0" xyz="0 0 0"/>
      <geometry>
        <mesh filename="package://steve_description/meshes/ability_hand/idx-F1.STL"/>
      </geometry>
    </collision>
  </link>
  <link name="middle_L2">
    <inertial>
      <mass value="0.00645"/>
      <inertia ixx="0.82671e-6" ixy="-1.08876e-6" ixz="-0.00037e-6" iyy="1.98028e-6" iyz="0.00081e-6" izz="2.64638e-6"/>
      <origin rpy="0 0 0" xyz="13.36818e-3 -8.75392e-3 -0.02886e-3"/>
    </inertial>
    <visual name="middle_mesh_2">
      <origin rpy="0 0 0" xyz="0 0 0"/>
      <geometry>
        <mesh filename="package://steve_description/meshes/ability_hand/idx-F2-Lg-2.STL"/>
      </geometry>
      <material name="black"/>
    </visual>
    <collision>
      <origin rpy="0 0 0" xyz="0 0 0"/>
      <geometry>
        <mesh filename="package://steve_description/meshes/ability_hand/idx-F2-Lg-2.STL"/>
      </geometry>
    </collision>
  </link>
  <joint name="middle_joint" type="revolute">
    <parent link="thumb_base"/>
    <child link="middle_L1"/>
    <origin rpy=" -1.2810616535897934 1.308458 -1.2453756535897933 " xyz=" -9.653191e-3 -15.310271e-3 -67.853949e-3 "/>
    <limit effort="6.0" lower="0" upper="2.0943951" velocity="8.0677777442"/>
    <!-- angles in rad, efforts in N-m, velocity in rad/s -->
    <dynamics damping="0.001" friction="0.001"/>
    <!-- Friction coefficient is not from quantitative measurement -->
    <axis xyz="0 0 1"/>
  </joint>
  <joint name="middle_mimic_joint" type="revolute">
    <parent link="middle_L1"/>
    <child link="middle_L2"/>
    <origin rpy="0 0 0" xyz="38.472723e-3 3.257695e-3 0.000000"/>
    <axis xyz="0 0 1"/>
    <limit effort="6.0" lower="0.0" upper="2.6586" velocity="8.0677777442"/>
    <!-- angles in rad, efforts in N-m, velocity in rad/s -->
    <dynamics damping="0.001" friction="0.001"/>
    <!-- Friction coefficient is not from quantitative measurement -->
    <mimic joint="middle_joint" multiplier="1.05851325" offset="0.2"/>
  </joint>
  <link name="middle_anchor"/>
  <joint name="mid_anchor" type="fixed">
    <parent link="middle_L2"/>
    <child link="middle_anchor"/>
    <origin rpy="0 0 0" xyz="31.5541e-3  -10.44e-3 0.14e-3"/>
  </joint>
  <link name="ring_L1">
    <inertial>
      <mass value="0.00635888"/>
      <inertia ixx="0.29766e-6" ixy="-0.06447133e-6" ixz="-0.00423315e-6" iyy="3.6947967e-6" iyz="0.00083028e-6" izz="3.8176336e-6"/>
      <origin rpy="0 0 0" xyz="22.41911e-3 -0.15798201e-3 -0.01319866e-3"/>
    </inertial>
    <visual name="ring_mesh_1">
      <origin rpy="0 0 0" xyz="0 0 0"/>
      <geometry>
        <mesh filename="package://steve_description/meshes/ability_hand/idx-F1.STL"/>
      </geometry>
      <material name="black"/>
    </visual>
    <collision>
      <origin rpy="0 0 0" xyz="0 0 0"/>
      <geometry>
        <mesh filename="package://steve_description/meshes/ability_hand/idx-F1.STL"/>
      </geometry>
    </collision>
  </link>
  <link name="ring_L2">
    <inertial>
      <mass value="0.00645"/>
      <inertia ixx="0.82671e-6" ixy="-1.08876e-6" ixz="-0.00037e-6" iyy="1.98028e-6" iyz="0.00081e-6" izz="2.64638e-6"/>
      <origin rpy="0 0 0" xyz="13.36818e-3 -8.75392e-3 -0.02886e-3"/>
    </inertial>
    <visual name="ring_mesh_2">
      <origin rpy="0 0 0" xyz="0 0 0"/>
      <geometry>
        <mesh filename="package://steve_description/meshes/ability_hand/idx-F2-Lg-2.STL"/>
      </geometry>
      <material name="black"/>
    </visual>
    <collision>
      <origin rpy="0 0 0" xyz="0 0 0"/>
      <geometry>
        <mesh filename="package://steve_description/meshes/ability_hand/idx-F2-Lg-2.STL"/>
      </geometry>
    </collision>
  </link>
  <joint name="ring_joint" type="revolute">
    <parent link="thumb_base"/>
    <child link="ring_L1"/>
    <origin rpy=" -1.424994653589793 1.321452 -1.4657306535897934 " xyz=" -29.95426e-3 -14.212492e-3 -67.286105e-3 "/>
    <limit effort="6.0" lower="0" upper="2.0943951" velocity="8.0677777442"/>
    <!-- angles in rad, efforts in N-m, velocity in rad/s -->
    <dynamics damping="0.001" friction="0.001"/>
    <!-- Friction coefficient is not from quantitative measurement -->
    <axis xyz="0 0 1"/>
  </joint>
  <joint name="ring_mimic_joint" type="revolute">
    <parent link="ring_L1"/>
    <child link="ring_L2"/>
    <origin rpy="0 0 0" xyz="38.472723e-3 3.257695e-3 0.000000"/>
    <axis xyz="0 0 1"/>
    <limit effort="6.0" lower="0.0" upper="2.6586" velocity="8.0677777442"/>
    <!-- angles in rad, efforts in N-m, velocity in rad/s -->
    <dynamics damping="0.001" friction="0.001"/>
    <!-- Friction coefficient is not from quantitative measurement -->
    <mimic joint="ring_joint" multiplier="1.05851325" offset="0.2"/>
  </joint>
  <link name="ring_anchor"/>
  <joint name="rng_anchor" type="fixed">
    <parent link="ring_L2"/>
    <child link="ring_anchor"/>
    <origin rpy="0 0 0" xyz="31.5541e-3  -10.44e-3 0.14e-3"/>
  </joint>
  <link name="pinky_L1">
    <inertial>
      <mass value="0.00635888"/>
      <inertia ixx="0.29766e-6" ixy="-0.06447133e-6" ixz="-0.00423315e-6" iyy="3.6947967e-6" iyz="0.00083028e-6" izz="3.8176336e-6"/>
      <origin rpy="0 0 0" xyz="22.41911e-3 -0.15798201e-3 -0.01319866e-3"/>
    </inertial>
    <visual name="pinky_mesh_1">
      <origin rpy="0 0 0" xyz="0 0 0"/>
      <geometry>
        <mesh filename="package://steve_description/meshes/ability_hand/idx-F1.STL"/>
      </geometry>
      <material name="black"/>
    </visual>
    <collision>
      <origin rpy="0 0 0" xyz="0 0 0"/>
      <geometry>
        <mesh filename="package://steve_description/meshes/ability_hand/idx-F1.STL"/>
      </geometry>
    </collision>
  </link>
  <link name="pinky_L2">
    <inertial>
      <mass value="0.00645"/>
      <inertia ixx="0.82671e-6" ixy="-1.08876e-6" ixz="-0.00037e-6" iyy="1.98028e-6" iyz="0.00081e-6" izz="2.64638e-6"/>
      <origin rpy="0 0 0" xyz="13.36818e-3 -8.75392e-3 -0.02886e-3"/>
    </inertial>
    <visual name="pinky_mesh_2">
      <origin rpy="0 0 0" xyz="0 0 0"/>
      <geometry>
        <mesh filename="package://steve_description/meshes/ability_hand/idx-F2-Lg-2.STL"/>
      </geometry>
      <material name="black"/>
    </visual>
    <collision>
      <origin rpy="0 0 0" xyz="0 0 0"/>
      <geometry>
        <mesh filename="package://steve_description/meshes/ability_hand/idx-F2-Lg-2.STL"/>
      </geometry>
    </collision>
  </link>
  <joint name="pinky_joint" type="revolute">
    <parent link="thumb_base"/>
    <child link="pinky_L1"/>
    <origin rpy=" -1.3764826535897934 1.32222 -1.4832096535897932 " xyz=" -49.521293e-3 -11.004583e-3 -63.029065e-3 "/>
    <limit effort="6.0" lower="0" upper="2.0943951" velocity="8.0677777442"/>
    <!-- angles in rad, efforts in N-m, velocity in rad/s -->
    <dynamics damping="0.001" friction="0.001"/>
    <!-- Friction coefficient is not from quantitative measurement -->
    <axis xyz="0 0 1"/>
  </joint>
  <joint name="pinky_mimic_joint" type="revolute">
    <parent link="pinky_L1"/>
    <child link="pinky_L2"/>
    <origin rpy="0 0 0" xyz="38.472723e-3 3.257695e-3 0.000000"/>
    <limit effort="6.0" lower="0.0" upper="2.6586" velocity="8.0677777442"/>
    <!-- angles in rad, efforts in N-m, velocity in rad/s -->
    <dynamics damping="0.001" friction="0.001"/>
    <!-- Friction coefficient is not from quantitative measurement -->
    <axis xyz="0 0 1"/>
    <mimic joint="pinky_joint" multiplier="1.05851325" offset="0.2"/>
  </joint>
  <link name="pinky_anchor"/>
  <joint name="pnky_anchor" type="fixed">
    <parent link="pinky_L2"/>
    <child link="pinky_anchor"/>
    <origin rpy="0 0 0" xyz="31.5541e-3  -10.44e-3 0.14e-3"/>
  </joint>
  <link name="thumb_L1">
    <inertial>
      <mass value="0.002"/>
      <inertia ixx="1.0" ixy="0.0" ixz="0.0" iyy="1.0" iyz="0.0" izz="1.0"/>
    </inertial>
    <visual name="thumb_mesh_1">
      <origin rpy="0 0 0" xyz="0 0 0"/>
      <geometry>
        <mesh filename="package://steve_description/meshes/ability_hand/thumb-F1-MIR.STL"/>
      </geometry>
      <material name="black"/>
    </visual>
    <collision>
      <origin rpy="0 0 0" xyz="0 0 0"/>
      <geometry>
        <mesh filename="package://steve_description/meshes/ability_hand/thumb-F1-MIR.STL"/>
      </geometry>
    </collision>
  </link>
  <link name="thumb_L2">
    <inertial>
      <mass value="0.002"/>
      <inertia ixx="1.0" ixy="0.0" ixz="0.0" iyy="1.0" iyz="0.0" izz="1.0"/>
    </inertial>
    <visual name="thumb_mesh_2">
      <origin rpy="0 0 0" xyz="0 0 0"/>
      <geometry>
        <mesh filename="package://steve_description/meshes/ability_hand/thumb-F2-right.STL"/>
      </geometry>
      <material name="black"/>
    </visual>
    <collision>
      <origin rpy="0 0 0" xyz="0 0 0"/>
      <geometry>
        <mesh filename="package://steve_description/meshes/ability_hand/thumb-F2-right.STL"/>
      </geometry>
    </collision>
  </link>
  <joint name="thumb1_joint" type="revolute">
    <parent link="thumb_base"/>
    <child link="thumb_L1"/>
    <origin rpy=" 3.141592653589793 -0.0 -0.18884434641020664 " xyz=" 0.0 0.0 0.0 "/>
    <axis xyz="0 0 1"/>
    <limit effort="1.2" lower="-2.0943951" upper="0" velocity="40.338888721"/>
    <!-- angles in rad, efforts in N-m, velocity in rad/s -->
    <dynamics damping="0.001" friction="0.001"/>
    <!-- Friction coefficient is not from quantitative measurement -->
  </joint>
  <joint name="thumb2_joint" type="revolute">
    <parent link="thumb_L1"/>
    <child link="thumb_L2"/>
    <origin rpy=" 1.832595714594045 -0.0 5.366520605522463e-18 " xyz=" 27.8283501e-3 1.7436510745838653e-19 14.7507e-3 "/>
    <axis xyz="0 0 1"/>
    <limit effort="6.0" lower="0" upper="2.0943951" velocity="8.0677777442"/>
    <!-- angles in rad, efforts in N-m, velocity in rad/s -->
    <dynamics damping="0.001" friction="0.001"/>
    <!-- Friction coefficient is not from quantitative measurement -->
  </joint>
  <link name="thumb_anchor"/>
  <joint name="thmb_anchor" type="fixed">
    <parent link="thumb_L2"/>
    <child link="thumb_anchor"/>
    <origin rpy="0 0 0" xyz="52.00122724e-3 28.00869333e-3 6.98483578e-3"/>
  </joint>
  <sensor name="fsr1">
    <parent link="index_L2"/>
    <origin rpy="[-1.57079633  1.11908681 -1.57079633]" xyz="[ 0.03678129 -0.01966348  0.        ]"/>
  </sensor>
  <sensor name="fsr2">
    <parent link="index_L2"/>
    <origin rpy="[ 1.57079633 -0.25241514  1.57079633]" xyz="[ 0.03087755 -0.01531625  0.        ]"/>
  </sensor>
  <sensor name="fsr3">
    <parent link="index_L2"/>
    <origin rpy="[-1.57079633  0.51757639 -1.57079633]" xyz="[ 0.03118107 -0.01775288  0.004     ]"/>
  </sensor>
  <sensor name="fsr4">
    <parent link="index_L2"/>
    <origin rpy="[-1.57079633  0.66148388 -1.57079633]" xyz="[ 0.01680497 -0.01308243  0.004     ]"/>
  </sensor>
  <sensor name="fsr5">
    <parent link="index_L2"/>
    <origin rpy="[-1.57079633  0.51757639 -1.57079633]" xyz="[ 0.03118107 -0.01775288 -0.004     ]"/>
  </sensor>
  <sensor name="fsr6">
    <parent link="index_L2"/>
    <origin rpy="[-1.57079633  0.66148388 -1.57079633]" xyz="[ 0.01680497 -0.01308243 -0.004     ]"/>
  </sensor>
  <sensor name="fsr7">
    <parent link="middle_L2"/>
    <origin rpy="[-1.57079633  1.11908681 -1.57079633]" xyz="[ 0.03678129 -0.01966348  0.        ]"/>
  </sensor>
  <sensor name="fsr8">
    <parent link="middle_L2"/>
    <origin rpy="[ 1.57079633 -0.25241514  1.57079633]" xyz="[ 0.03087755 -0.01531625  0.        ]"/>
  </sensor>
  <sensor name="fsr9">
    <parent link="middle_L2"/>
    <origin rpy="[-1.57079633  0.51757639 -1.57079633]" xyz="[ 0.03118107 -0.01775288  0.004     ]"/>
  </sensor>
  <sensor name="fsr10">
    <parent link="middle_L2"/>
    <origin rpy="[-1.57079633  0.66148388 -1.57079633]" xyz="[ 0.01680497 -0.01308243  0.004     ]"/>
  </sensor>
  <sensor name="fsr11">
    <parent link="middle_L2"/>
    <origin rpy="[-1.57079633  0.51757639 -1.57079633]" xyz="[ 0.03118107 -0.01775288 -0.004     ]"/>
  </sensor>
  <sensor name="fsr12">
    <parent link="middle_L2"/>
    <origin rpy="[-1.57079633  0.66148388 -1.57079633]" xyz="[ 0.01680497 -0.01308243 -0.004     ]"/>
  </sensor>
  <sensor name="fsr13">
    <parent link="ring_L2"/>
    <origin rpy="[-1.57079633  1.11908681 -1.57079633]" xyz="[ 0.03678129 -0.01966348  0.        ]"/>
  </sensor>
  <sensor name="fsr14">
    <parent link="ring_L2"/>
    <origin rpy="[ 1.57079633 -0.25241514  1.57079633]" xyz="[ 0.03087755 -0.01531625  0.        ]"/>
  </sensor>
  <sensor name="fsr15">
    <parent link="ring_L2"/>
    <origin rpy="[-1.57079633  0.51757639 -1.57079633]" xyz="[ 0.03118107 -0.01775288  0.004     ]"/>
  </sensor>
  <sensor name="fsr16">
    <parent link="ring_L2"/>
    <origin rpy="[-1.57079633  0.66148388 -1.57079633]" xyz="[ 0.01680497 -0.01308243  0.004     ]"/>
  </sensor>
  <sensor name="fsr17">
    <parent link="ring_L2"/>
    <origin rpy="[-1.57079633  0.51757639 -1.57079633]" xyz="[ 0.03118107 -0.01775288 -0.004     ]"/>
  </sensor>
  <sensor name="fsr18">
    <parent link="ring_L2"/>
    <origin rpy="[-1.57079633  0.66148388 -1.57079633]" xyz="[ 0.01680497 -0.01308243 -0.004     ]"/>
  </sensor>
  <sensor name="fsr19">
    <parent link="pinky_L2"/>
    <origin rpy="[-1.57079633  1.11908681 -1.57079633]" xyz="[ 0.03678129 -0.01966348  0.        ]"/>
  </sensor>
  <sensor name="fsr20">
    <parent link="pinky_L2"/>
    <origin rpy="[ 1.57079633 -0.25241514  1.57079633]" xyz="[ 0.03087755 -0.01531625  0.        ]"/>
  </sensor>
  <sensor name="fsr21">
    <parent link="pinky_L2"/>
    <origin rpy="[-1.57079633  0.51757639 -1.57079633]" xyz="[ 0.03118107 -0.01775288  0.004     ]"/>
  </sensor>
  <sensor name="fsr22">
    <parent link="pinky_L2"/>
    <origin rpy="[-1.57079633  0.66148388 -1.57079633]" xyz="[ 0.01680497 -0.01308243  0.004     ]"/>
  </sensor>
  <sensor name="fsr23">
    <parent link="pinky_L2"/>
    <origin rpy="[-1.57079633  0.51757639 -1.57079633]" xyz="[ 0.03118107 -0.01775288 -0.004     ]"/>
  </sensor>
  <sensor name="fsr24">
    <parent link="pinky_L2"/>
    <origin rpy="[-1.57079633  0.66148388 -1.57079633]" xyz="[ 0.01680497 -0.01308243 -0.004     ]"/>
  </sensor>
  <sensor name="fsr25">
    <parent link="thumb_L2"/>
    <origin rpy="[-1.57079633 -0.40123853 -1.57079633]" xyz="[0.055422 0.023513 0.005055]"/>
  </sensor>
  <sensor name="fsr26">
    <parent link="thumb_L2"/>
    <origin rpy="[-1.57079633 -0.44961601 -1.57079633]" xyz="[0.047909 0.02312  0.005728]"/>
  </sensor>
  <sensor name="fsr27">
    <parent link="thumb_L2"/>
    <origin rpy="[-1.57079633 -0.43229053 -1.57079633]" xyz="[ 0.048227  0.022352 -0.000805]"/>
  </sensor>
  <sensor name="fsr28">
    <parent link="thumb_L2"/>
    <origin rpy="[nan nan nan]" xyz="[ 0.036868  0.017111 -0.001369]"/>
  </sensor>
  <sensor name="fsr29">
    <parent link="thumb_L2"/>
    <origin rpy="[-1.57079633 -0.44946695 -1.57079633]" xyz="[0.049435 0.019437 0.01097 ]"/>
  </sensor>
  <sensor name="fsr30">
    <parent link="thumb_L2"/>
    <origin rpy="[nan nan nan]" xyz="[0.038158 0.013997 0.011211]"/>
  </sensor>
  <!-- transmissoins -->
  <transmission name="index_joint_transmission">
    <type>transmission_interface/SimpleTransmission</type>
    <joint name="index_joint">
      <hardwareInterface>hardware_interface/PositionJointInterface</hardwareInterface>
    </joint>
    <actuator name="index_joint_motor">
      <mechanicalReduction>1.0</mechanicalReduction>
    </actuator>
  </transmission>
  <transmission name="middle_joint_transmission">
    <type>transmission_interface/SimpleTransmission</type>
    <joint name="middle_joint">
      <hardwareInterface>hardware_interface/PositionJointInterface</hardwareInterface>
    </joint>
    <actuator name="middle_joint_motor">
      <mechanicalReduction>1.0</mechanicalReduction>
    </actuator>
  </transmission>
  <transmission name="ring_joint_transmission">
    <type>transmission_interface/SimpleTransmission</type>
    <joint name="ring_joint">
      <hardwareInterface>hardware_interface/PositionJointInterface</hardwareInterface>
    </joint>
    <actuator name="ring_joint_motor">
      <mechanicalReduction>1.0</mechanicalReduction>
    </actuator>
  </transmission>
  <transmission name="pinky_joint_transmission">
    <type>transmission_interface/SimpleTransmission</type>
    <joint name="pinky_joint">
      <hardwareInterface>hardware_interface/PositionJointInterface</hardwareInterface>
    </joint>
    <actuator name="pinky_joint_motor">
      <mechanicalReduction>1.0</mechanicalReduction>
    </actuator>
  </transmission>
  <transmission name="thumb1_joint_transmission">
    <type>transmission_interface/SimpleTransmission</type>
    <joint name="thumb1_joint">
      <hardwareInterface>hardware_interface/PositionJointInterface</hardwareInterface>
    </joint>
    <actuator name="thumb1_joint_motor">
      <mechanicalReduction>1.0</mechanicalReduction>
    </actuator>
  </transmission>
  <transmission name="thumb2_joint_transmission">
    <type>transmission_interface/SimpleTransmission</type>
    <joint name="thumb2_joint">
      <hardwareInterface>hardware_interface/PositionJointInterface</hardwareInterface>
    </joint>
    <actuator name="thumb2_joint_motor">
      <mechanicalReduction>1.0</mechanicalReduction>
    </actuator>
  </transmission>
  <!-- gazebo self collidde -->
  <gazebo reference="hand_mount">
    <selfCollide>true</selfCollide>
  </gazebo>
  <gazebo reference="hand_base">
    <selfCollide>true</selfCollide>
  </gazebo>
  <gazebo reference="thumb_L1">
    <selfCollide>true</selfCollide>
  </gazebo>
  <gazebo reference="thumb_L2">
    <selfCollide>true</selfCollide>
  </gazebo>
  <gazebo reference="thumb_base">
    <selfCollide>true</selfCollide>
  </gazebo>
  <gazebo reference="thumb_anchor">
    <selfCollide>true</selfCollide>
  </gazebo>
  <gazebo reference="index_L1">
    <selfCollide>true</selfCollide>
  </gazebo>
  <gazebo reference="index_L2">
    <selfCollide>true</selfCollide>
  </gazebo>
  <gazebo reference="index_anchor">
    <selfCollide>true</selfCollide>
  </gazebo>
  <gazebo reference="middle_L1">
    <selfCollide>true</selfCollide>
  </gazebo>
  <gazebo reference="middle_L2">
    <selfCollide>true</selfCollide>
  </gazebo>
  <gazebo reference="middle_anchor">
    <selfCollide>true</selfCollide>
  </gazebo>
  <gazebo reference="ring_L1">
    <selfCollide>true</selfCollide>
  </gazebo>
  <gazebo reference="ring_L2">
    <selfCollide>true</selfCollide>
  </gazebo>
  <gazebo reference="ring_anchor">
    <selfCollide>true</selfCollide>
  </gazebo>
  <gazebo reference="pinky_L1">
    <selfCollide>true</selfCollide>
  </gazebo>
  <gazebo reference="pinky_L2">
    <selfCollide>true</selfCollide>
  </gazebo>
  <gazebo reference="pinky_anchor">
    <selfCollide>true</selfCollide>
  </gazebo>
  <!-- ****************************************************************** -->
  <!-- ====================== PAN-TILT TOWER ============================ -->
  <!-- ****************************************************************** -->
  <material name="tower_material">
    <color rgba="0.7 0.7 0.7 1"/>
  </material>
  <!-- Tower mount base link -->
  <link name="pan_tilt_tower_base">
    <visual>
      <geometry>
        <mesh filename="package://steve_description/meshes/pan_tilt_tower/pan_tilt_tower.stl" scale="0.001 0.001 0.001"/>
      </geometry>
      <material name="tower_material"/>
    </visual>
    <collision>
      <geometry>
        <mesh filename="package://steve_description/meshes/pan_tilt_tower/pan_tilt_tower.stl" scale="0.001 0.001 0.001"/>
      </geometry>
    </collision>
    <inertial>
      <mass value="1.0"/>
      <inertia ixx="0.05" ixy="0" ixz="0" iyy="0.05" iyz="0" izz="0.05"/>
    </inertial>
  </link>
  <joint name="pan_tilt_tower_joint" type="fixed">
    <parent link="cabinet_link"/>
    <child link="pan_tilt_tower_base"/>
    <origin rpy="0.0 0.0 0.0" xyz="-0.2 0.0 0.424"/>
  </joint>
  <joint name="dynamixel_pan_tilt_pan_motor_base_joint" type="fixed">
    <origin rpy="2.1816615649929116 0.0 1.5707963267948966" xyz="0.02 0.0 1.047"/>
    <parent link="pan_tilt_tower_base"/>
    <child link="dynamixel_pan_tilt_pan_motor_base_link"/>
  </joint>
  <link name="dynamixel_pan_tilt_pan_motor_base_link">
    <inertial>
      <origin rpy="0 0 0" xyz="0 0 0"/>
      <mass value="0.05"/>
      <inertia ixx="0.01" ixy="0" ixz="0" iyy="0.01" iyz="0" izz="0.01"/>
    </inertial>
    <visual>
      <origin rpy="0 1.5707963267948966 0" xyz="0 0 0.0"/>
      <geometry>
        <mesh filename="package://steve_description/meshes/dynamixel/dynamixel_motor_xl-430.dae" scale="0.001 0.001 0.001"/>
      </geometry>
    </visual>
    <collision>
      <origin rpy="0 1.5707963267948966 0" xyz="0 0 0.0"/>
      <geometry>
        <mesh filename="package://steve_description/meshes/dynamixel/dynamixel_motor_xl-430_convex_hull.dae" scale="0.001 0.001 0.001"/>
      </geometry>
    </collision>
  </link>
  <joint name="dynamixel_pan_tilt_pan_motor_joint" type="revolute">
    <parent link="dynamixel_pan_tilt_pan_motor_base_link"/>
    <child link="dynamixel_pan_tilt_pan_motor_link"/>
    <origin rpy="0.065 0 3.141592653589793" xyz="0 0 0.0"/>
    <axis xyz="-1 0 0"/>
    <limit effort="1.5" lower="-3.141592653589793" upper="0.3490658503988659" velocity="6.178465545"/>
  </joint>
  <!-- <joint name="${name}_joint" type="revolute" >
      <parent link="${name}_base_link" />
      <child link="${name}_link" />
      <origin xyz="0 0 0.0" rpy="${position_offset} 0 ${pi}"/>
      <axis xyz="${motor_direction} 0 0"/>
      <limit effort="1.5" lower="-${pi / 180 * 110}" upper="${pi / 180 * 110}" velocity="6.178465545"/>
    </joint> -->
  <link name="dynamixel_pan_tilt_pan_motor_link">
    <inertial>
      <origin rpy="0 0 0" xyz="0 0 0"/>
      <mass value="0.001"/>
      <inertia ixx="0.01" ixy="0" ixz="0" iyy="0.01" iyz="0" izz="0.01"/>
    </inertial>
  </link>
  <gazebo reference="dynamixel_pan_tilt_pan_motor_link">
    <turnGravityOff>false</turnGravityOff>
  </gazebo>
  <transmission name="dynamixel_pan_tilt_pan_motor_trans">
    <type>transmission_interface/SimpleTransmission</type>
    <actuator name="dynamixel_pan_tilt_pan_motor_motor">
      <mechanicalReduction>1</mechanicalReduction>
    </actuator>
    <joint name="dynamixel_pan_tilt_pan_motor_joint">
      <hardwareInterface>hardware_interface/PositionJointInterface</hardwareInterface>
    </joint>
  </transmission>
  <joint name="dynamixel_pan_tilt_pan_bracket_joint" type="fixed">
    <origin rpy="1.5057963267948966 0 0" xyz="0 0 0"/>
    <parent link="dynamixel_pan_tilt_pan_motor_link"/>
    <child link="dynamixel_pan_tilt_pan_bracket_link"/>
  </joint>
  <link name="dynamixel_pan_tilt_pan_bracket_link">
    <inertial>
      <origin rpy="0 0 0" xyz="0 0 0"/>
      <mass value="0.05"/>
      <inertia ixx="0.01" ixy="0" ixz="0" iyy="0.01" iyz="0" izz="0.01"/>
    </inertial>
    <visual>
      <origin rpy="0 0 0" xyz="0 0 0"/>
      <geometry>
        <mesh filename="package://steve_description/meshes/dynamixel/dynamixel_bracket_fr12_h101.dae" scale="0.001 0.001 0.001"/>
      </geometry>
    </visual>
    <collision>
      <origin rpy="0 0 0" xyz="0 0 0"/>
      <geometry>
        <mesh filename="package://steve_description/meshes/dynamixel/dynamixel_bracket_fr12_h101_convex_hull.dae" scale="0.001 0.001 0.001"/>
      </geometry>
    </collision>
  </link>
  <joint name="dynamixel_pan_tilt_tilt_motor_base_joint" type="fixed">
    <origin rpy="0 1.5707963267948966 0" xyz="0 0.0633 0"/>
    <parent link="dynamixel_pan_tilt_pan_bracket_link"/>
    <child link="dynamixel_pan_tilt_tilt_motor_base_link"/>
  </joint>
  <link name="dynamixel_pan_tilt_tilt_motor_base_link">
    <inertial>
      <origin rpy="0 0 0" xyz="0 0 0"/>
      <mass value="0.05"/>
      <inertia ixx="0.01" ixy="0" ixz="0" iyy="0.01" iyz="0" izz="0.01"/>
    </inertial>
    <visual>
      <origin rpy="0 1.5707963267948966 0" xyz="0 0 0.0"/>
      <geometry>
        <mesh filename="package://steve_description/meshes/dynamixel/dynamixel_motor_xl-430.dae" scale="0.001 0.001 0.001"/>
      </geometry>
    </visual>
    <collision>
      <origin rpy="0 1.5707963267948966 0" xyz="0 0 0.0"/>
      <geometry>
        <mesh filename="package://steve_description/meshes/dynamixel/dynamixel_motor_xl-430_convex_hull.dae" scale="0.001 0.001 0.001"/>
      </geometry>
    </collision>
  </link>
  <joint name="dynamixel_pan_tilt_tilt_motor_joint" type="revolute">
    <parent link="dynamixel_pan_tilt_tilt_motor_base_link"/>
    <child link="dynamixel_pan_tilt_tilt_motor_link"/>
    <origin rpy="0.065 0 3.141592653589793" xyz="0 0 0.0"/>
    <axis xyz="-1 0 0"/>
    <limit effort="1.5" lower="-1.9198621771937625" upper="1.9198621771937625" velocity="6.178465545"/>
  </joint>
  <!-- <joint name="${name}_joint" type="revolute" >
      <parent link="${name}_base_link" />
      <child link="${name}_link" />
      <origin xyz="0 0 0.0" rpy="${position_offset} 0 ${pi}"/>
      <axis xyz="${motor_direction} 0 0"/>
      <limit effort="1.5" lower="-${pi / 180 * 110}" upper="${pi / 180 * 110}" velocity="6.178465545"/>
    </joint> -->
  <link name="dynamixel_pan_tilt_tilt_motor_link">
    <inertial>
      <origin rpy="0 0 0" xyz="0 0 0"/>
      <mass value="0.001"/>
      <inertia ixx="0.01" ixy="0" ixz="0" iyy="0.01" iyz="0" izz="0.01"/>
    </inertial>
  </link>
  <gazebo reference="dynamixel_pan_tilt_tilt_motor_link">
    <turnGravityOff>false</turnGravityOff>
  </gazebo>
  <transmission name="dynamixel_pan_tilt_tilt_motor_trans">
    <type>transmission_interface/SimpleTransmission</type>
    <actuator name="dynamixel_pan_tilt_tilt_motor_motor">
      <mechanicalReduction>1</mechanicalReduction>
    </actuator>
    <joint name="dynamixel_pan_tilt_tilt_motor_joint">
      <hardwareInterface>hardware_interface/PositionJointInterface</hardwareInterface>
    </joint>
  </transmission>
  <joint name="dynamixel_pan_tilt_tilt_bracket_joint" type="fixed">
    <origin rpy="3.076592653589793 0 0" xyz="0 0 0"/>
    <parent link="dynamixel_pan_tilt_tilt_motor_link"/>
    <child link="dynamixel_pan_tilt_tilt_bracket_link"/>
  </joint>
  <link name="dynamixel_pan_tilt_tilt_bracket_link">
    <inertial>
      <origin rpy="0 0 0" xyz="0 0 0"/>
      <mass value="0.05"/>
      <inertia ixx="0.01" ixy="0" ixz="0" iyy="0.01" iyz="0" izz="0.01"/>
    </inertial>
    <visual>
      <origin rpy="0 0 0" xyz="0 0 0"/>
      <geometry>
        <mesh filename="package://steve_description/meshes/dynamixel/dynamixel_bracket_fr12_h101.dae" scale="0.001 0.001 0.001"/>
      </geometry>
    </visual>
    <collision>
      <origin rpy="0 0 0" xyz="0 0 0"/>
      <geometry>
        <mesh filename="package://steve_description/meshes/dynamixel/dynamixel_bracket_fr12_h101_convex_hull.dae" scale="0.001 0.001 0.001"/>
      </geometry>
    </collision>
  </link>
  <material name="aluminum">
    <color rgba="0.5 0.5 0.5 1"/>
  </material>
  <material name="plastic">
    <color rgba="0.1 0.1 0.1 1"/>
  </material>
  <!-- this specific plug does not apply to L515 -->
  <!-- camera body, with origin at bottom screw mount -->
  <joint name="head_lidar_camera_joint" type="fixed">
    <origin rpy="-1.5707963267948966 0.0 1.5707963267948966" xyz="0.03 0.047 0.0"/>
    <parent link="dynamixel_pan_tilt_tilt_bracket_link"/>
    <child link="head_lidar_camera_bottom_screw_frame"/>
  </joint>
  <link name="head_lidar_camera_bottom_screw_frame"/>
  <joint name="head_lidar_camera_link_joint" type="fixed">
    <origin rpy="0 0 0" xyz="0.007500000000000001 0.0 0.021150000000000002"/>
    <parent link="head_lidar_camera_bottom_screw_frame"/>
    <child link="head_lidar_camera_link"/>
  </joint>
  <link name="head_lidar_camera_link">
    <visual>
      <origin rpy="1.5707963267948966 0 1.5707963267948966" xyz="0.0045 0 0.009000000000000001"/>
      <geometry>
        <mesh filename="package://steve_description/meshes/realsense/l515/l515.dae"/>
      </geometry>
    </visual>
    <collision>
      <origin rpy="1.5707963267948966 0 1.5707963267948966" xyz="-0.0085 0 0.009000000000000001"/>
      <geometry>
        <cylinder length="0.026" radius="0.0305"/>
      </geometry>
    </collision>
    <inertial>
      <!-- The following are not reliable values, and should not be used for modeling -->
      <!-- calculated assuming full cylinder as described here: https://en.wikipedia.org/wiki/List_of_moments_of_inertia -->
      <mass value="0.095"/>
      <origin xyz="0 0 0"/>
      <inertia ixx="0.000044" ixy="0.0" ixz="0.0" iyy="0.000027" iyz="0.0" izz="0.000027"/>
    </inertial>
  </link>
  <joint name="head_lidar_camera_lower_mount_joint" type="fixed">
    <origin rpy="0 0 0" xyz="-0.013999999999999999 0 0.01015"/>
    <parent link="head_lidar_camera_bottom_screw_frame"/>
    <child link="head_lidar_camera_lower_mount"/>
  </joint>
  <link name="head_lidar_camera_lower_mount"/>
  <joint name="head_lidar_camera_upper_mount_joint" type="fixed">
    <origin rpy="0 0 0" xyz="-0.013999999999999999 0 0.05015"/>
    <parent link="head_lidar_camera_bottom_screw_frame"/>
    <child link="head_lidar_camera_upper_mount"/>
  </joint>
  <link name="head_lidar_camera_upper_mount"/>
  <!-- camera depth joints and links -->
  <joint name="head_lidar_camera_depth_joint" type="fixed">
    <origin rpy="0 0 0" xyz="0 0 0"/>
    <parent link="head_lidar_camera_link"/>
    <child link="head_lidar_camera_depth_frame"/>
  </joint>
  <link name="head_lidar_camera_depth_frame"/>
  <joint name="head_lidar_camera_depth_optical_joint" type="fixed">
    <origin rpy="-1.5707963267948966 0 -1.5707963267948966" xyz="0 0 0"/>
    <parent link="head_lidar_camera_depth_frame"/>
    <child link="head_lidar_camera_depth_optical_frame"/>
  </joint>
  <link name="head_lidar_camera_depth_optical_frame"/>
  <!-- camera left IR joints and links -->
  <joint name="head_lidar_camera_infra_joint" type="fixed">
    <origin rpy="0 0 0" xyz="0 0.0 0"/>
    <parent link="head_lidar_camera_link"/>
    <child link="head_lidar_camera_infra_frame"/>
  </joint>
  <link name="head_lidar_camera_infra_frame"/>
  <joint name="head_lidar_camera_infra_optical_joint" type="fixed">
    <origin rpy="-1.5707963267948966 0 -1.5707963267948966" xyz="0 0 0"/>
    <parent link="head_lidar_camera_infra_frame"/>
    <child link="head_lidar_camera_infra_optical_frame"/>
  </joint>
  <link name="head_lidar_camera_infra_optical_frame"/>
  <!-- camera color joints and links -->
  <joint name="head_lidar_camera_color_joint" type="fixed">
    <origin rpy="0 0 0" xyz="0 0 0.024"/>
    <parent link="head_lidar_camera_link"/>
    <child link="head_lidar_camera_color_frame"/>
  </joint>
  <link name="head_lidar_camera_color_frame"/>
  <joint name="head_lidar_camera_color_optical_joint" type="fixed">
    <origin rpy="-1.5707963267948966 0 -1.5707963267948966" xyz="0 0 0"/>
    <parent link="head_lidar_camera_color_frame"/>
    <child link="head_lidar_camera_color_optical_frame"/>
  </joint>
  <link name="head_lidar_camera_color_optical_frame"/>
  <!-- camera IMU joints and links -->
  <link name="head_lidar_camera_gyro_frame"/>
  <link name="head_lidar_camera_gyro_optical_frame"/>
  <link name="head_lidar_camera_accel_frame"/>
  <link name="head_lidar_camera_accel_optical_frame"/>
  <joint name="head_lidar_camera_gyro_joint" type="fixed">
    <origin rpy="-0.006161012 0.020193459 0.016301375" xyz="-0.00410137791186571 -0.0129784867167473 0.00256138201802969"/>
    <parent link="head_lidar_camera_color_frame"/>
    <child link="head_lidar_camera_gyro_frame"/>
  </joint>
  <joint name="head_lidar_camera_gyro_optical_joint" type="fixed">
    <origin rpy="-1.5707963267948966 0 -1.5707963267948966" xyz="0 0 0"/>
    <parent link="head_lidar_camera_gyro_frame"/>
    <child link="head_lidar_camera_gyro_optical_frame"/>
  </joint>
  <joint name="head_lidar_camera_accel_joint" type="fixed">
    <origin rpy="-0.006161012 0.020193459 0.016301375" xyz="-0.00410137791186571 -0.0129784867167473 0.00256138201802969"/>
    <parent link="head_lidar_camera_color_frame"/>
    <child link="head_lidar_camera_accel_frame"/>
  </joint>
  <joint name="head_lidar_camera_accel_optical_joint" type="fixed">
    <origin rpy="-1.5707963267948966 0 -1.5707963267948966" xyz="0 0 0"/>
    <parent link="head_lidar_camera_accel_frame"/>
    <child link="head_lidar_camera_accel_optical_frame"/>
  </joint>
  <joint name="head_lidar_camera_usb_plug_joint" type="fixed">
    <origin rpy="0.7853981633974483 0 0 " xyz="-0.0028000000000000004 -0.018 0.018"/>
    <parent link="head_lidar_camera_bottom_screw_frame"/>
    <child link="head_lidar_camera_usb_plug_link"/>
  </joint>
  <link name="head_lidar_camera_usb_plug_link">
    <visual>
      <!-- 0.044850 0.008000 0.018500 -->
      <origin rpy="0 0 1.5707963267948966" xyz="0. -0.022425 0."/>
      <geometry>
        <!--box size="0.044850 0.008 0.0185" /-->
        <mesh filename="package://steve_description/meshes/realsense/l515/plug.stl"/>
      </geometry>
      <material name="plastic"/>
    </visual>
    <collision>
      <origin rpy="0 0 1.5707963267948966" xyz="0. -0.022425 0."/>
      <geometry>
        <!--box size="0.044850 0.008 0.0185" /-->
        <mesh filename="package://steve_description/meshes/realsense/l515/plug_collision.stl"/>
      </geometry>
    </collision>
  </link>
  <gazebo reference="head_lidar_camera_link">
    <self_collide>0</self_collide>
    <enable_wind>0</enable_wind>
    <kinematic>0</kinematic>
    <gravity>1</gravity>
    <!--<mu>1</mu>-->
    <mu2>1</mu2>
    <fdir1>0 0 0</fdir1>
    <!--<slip1>0</slip1>
      <slip2>0</slip2>-->
    <kp>1e+13</kp>
    <kd>1</kd>
    <!--<max_vel>0.01</max_vel>
      <min_depth>0</min_depth>-->
    <sensor name="head_lidar_cameracolor" type="camera">
      <camera name="head_lidar_camera">
        <horizontal_fov>1.2393583018411736</horizontal_fov>
        <image>
          <width>1920</width>
          <height>1080</height>
          <format>RGB_INT8</format>
        </image>
        <clip>
          <near>0.1</near>
          <far>100</far>
        </clip>
        <noise>
          <type>gaussian</type>
          <mean>0.0</mean>
          <stddev>0.007</stddev>
        </noise>
      </camera>
      <always_on>1</always_on>
      <update_rate>30</update_rate>
      <visualize>1</visualize>
    </sensor>
    <sensor name="head_lidar_cameraired" type="camera">
      <camera name="head_lidar_camera">
        <horizontal_fov>1.2217304763960306</horizontal_fov>
        <image>
          <width>1024</width>
          <height>768</height>
          <format>L_INT8</format>
        </image>
        <clip>
          <near>0.1</near>
          <far>100</far>
        </clip>
        <noise>
          <type>gaussian</type>
          <mean>0.0</mean>
          <stddev>0.05</stddev>
        </noise>
      </camera>
      <always_on>1</always_on>
      <update_rate>90</update_rate>
      <visualize>0</visualize>
    </sensor>
    <sensor name="head_lidar_cameradepth" type="depth">
      <camera name="head_lidar_camera">
        <horizontal_fov>1.2217304763960306</horizontal_fov>
        <image>
          <width>1024</width>
          <height>768</height>
        </image>
        <clip>
          <near>0.1</near>
          <far>100</far>
        </clip>
        <noise>
          <type>gaussian</type>
          <mean>0.0</mean>
          <stddev>0.100</stddev>
        </noise>
      </camera>
      <always_on>1</always_on>
      <update_rate>90</update_rate>
      <visualize>0</visualize>
    </sensor>
  </gazebo>
  <gazebo>
    <plugin filename="librealsense_gazebo_plugin.so" name="realsense_l515">
      <prefix>head_lidar_camera</prefix>
      <depthUpdateRate>30.0</depthUpdateRate>
      <colorUpdateRate>30.0</colorUpdateRate>
      <infraredUpdateRate>30.0</infraredUpdateRate>
      <depthTopicName>/camera/depth/image_rect_raw</depthTopicName>
      <depthCameraInfoTopicName>/camera/depth/camera_info</depthCameraInfoTopicName>
      <colorTopicName>/camera/color/image_raw</colorTopicName>
      <colorCameraInfoTopicName>/camera/color/camera_info</colorCameraInfoTopicName>
      <infraredTopicName>/camera/infra/image_raw</infraredTopicName>
      <infraredCameraInfoTopicName>/camera/infra/camera_info</infraredCameraInfoTopicName>
      <colorOpticalframeName>head_lidar_camera_color_optical_frame</colorOpticalframeName>
      <depthOpticalframeName>head_lidar_camera_depth_optical_frame</depthOpticalframeName>
      <infraredOpticalframeName>head_lidar_camera_infra_optical_frame</infraredOpticalframeName>
      <rangeMinDepth>0.2</rangeMinDepth>
      <rangeMaxDepth>10.0</rangeMaxDepth>
      <pointCloud>False</pointCloud>
      <pointCloudTopicName>/camera/depth/color/points</pointCloudTopicName>
      <pointCloudCutoff>0.25</pointCloudCutoff>
      <pointCloudCutoffMax>9.0</pointCloudCutoffMax>
    </plugin>
  </gazebo>
  <material name="grey">
    <color rgba="0.5 0.5 0.5 1"/>
  </material>
  <link name="ur5_wrist_cam_mount_link">
    <visual>
      <origin rpy="0 0 0" xyz="0 0 0"/>
      <geometry>
        <mesh filename="package://steve_description/meshes/ur5_wrist_cam_mount/ur5_wrist_cam_mount.STL" scale="0.001 0.001 0.001"/>
      </geometry>
      <material name="grey"/>
    </visual>
    <collision>
      <origin rpy="0 0 0" xyz="0 0 0"/>
      <geometry>
        <mesh filename="package://steve_description/meshes/ur5_wrist_cam_mount/ur5_wrist_cam_mount.STL" scale="0.001 0.001 0.001"/>
      </geometry>
    </collision>
  </link>
  <joint name="ur5e_wrist_3_link_wrist_d405_mount_joint" type="fixed">
    <parent link="ur5e_wrist_3_link"/>
    <child link="ur5_wrist_cam_mount_link"/>
    <origin rpy="0.0 0.0 1.5707963267948966" xyz="0.0 0.0 -0.03"/>
  </joint>
  <!-- camera body, with origin at bottom screw mount -->
  <joint name="wrist_camera_joint" type="fixed">
    <origin rpy="3.141592653589793 -1.7707963267948965 0.0" xyz="0.08 0.0 0.05"/>
    <parent link="ur5_wrist_cam_mount_link"/>
    <child link="wrist_camera_bottom_screw_frame"/>
  </joint>
  <link name="wrist_camera_bottom_screw_frame"/>
  <joint name="wrist_camera_link_joint" type="fixed">
    <origin rpy="0 0 0" xyz="0.01085 0.009 0.021"/>
    <parent link="wrist_camera_bottom_screw_frame"/>
    <child link="wrist_camera_link"/>
  </joint>
  <link name="wrist_camera_link">
    <visual>
      <!-- the mesh origin is at front plate in between the two infrared camera axes -->
      <origin rpy="1.5707963267948966 0 1.5707963267948966" xyz="0.0038 -0.009 0"/>
      <geometry>
        <mesh filename="package://steve_description/meshes/realsense/d405/d405.stl" scale="0.001 0.001 0.001"/>
      </geometry>
      <material name="aluminum"/>
    </visual>
    <collision>
      <origin rpy="0 0 0" xyz="-0.0078 -0.009 0"/>
      <geometry>
        <box size="0.023 0.042 0.042"/>
      </geometry>
    </collision>
    <inertial>
      <!-- The following are not reliable values, and should not be used for modeling -->
      <mass value="0.072"/>
      <origin xyz="0 0 0"/>
      <inertia ixx="0.003881243" ixy="0.0" ixz="0.0" iyy="0.000498940" iyz="0.0" izz="0.003879257"/>
    </inertial>
  </link>
  <!-- camera depth joints and links -->
  <joint name="wrist_camera_depth_joint" type="fixed">
    <origin rpy="0 0 0" xyz="0 0 0"/>
    <parent link="wrist_camera_link"/>
    <child link="wrist_camera_depth_frame"/>
  </joint>
  <link name="wrist_camera_depth_frame"/>
  <joint name="wrist_camera_depth_optical_joint" type="fixed">
    <origin rpy="-1.5707963267948966 0 -1.5707963267948966" xyz="0 0 0"/>
    <parent link="wrist_camera_depth_frame"/>
    <child link="wrist_camera_depth_optical_frame"/>
  </joint>
  <link name="wrist_camera_depth_optical_frame"/>
  <!-- camera left IR joints and links -->
  <joint name="wrist_camera_infra1_joint" type="fixed">
    <origin rpy="0 0 0" xyz="0 0.0 0"/>
    <parent link="wrist_camera_link"/>
    <child link="wrist_camera_infra1_frame"/>
  </joint>
  <link name="wrist_camera_infra1_frame"/>
  <joint name="wrist_camera_infra1_optical_joint" type="fixed">
    <origin rpy="-1.5707963267948966 0 -1.5707963267948966" xyz="0 0 0"/>
    <parent link="wrist_camera_infra1_frame"/>
    <child link="wrist_camera_infra1_optical_frame"/>
  </joint>
  <link name="wrist_camera_infra1_optical_frame"/>
  <!-- camera right IR joints and links -->
  <joint name="wrist_camera_infra2_joint" type="fixed">
    <origin rpy="0 0 0" xyz="0 -0.018 0"/>
    <parent link="wrist_camera_link"/>
    <child link="wrist_camera_infra2_frame"/>
  </joint>
  <link name="wrist_camera_infra2_frame"/>
  <joint name="wrist_camera_infra2_optical_joint" type="fixed">
    <origin rpy="-1.5707963267948966 0 -1.5707963267948966" xyz="0 0 0"/>
    <parent link="wrist_camera_infra2_frame"/>
    <child link="wrist_camera_infra2_optical_frame"/>
  </joint>
  <link name="wrist_camera_infra2_optical_frame"/>
  <!-- camera color joints and links -->
  <joint name="wrist_camera_color_joint" type="fixed">
    <origin rpy="0 0 0" xyz="0 0.0 0"/>
    <parent link="wrist_camera_link"/>
    <child link="wrist_camera_color_frame"/>
  </joint>
  <link name="wrist_camera_color_frame"/>
  <joint name="wrist_camera_color_optical_joint" type="fixed">
    <origin rpy="-1.5707963267948966 0 -1.5707963267948966" xyz="0 0 0"/>
    <parent link="wrist_camera_color_frame"/>
    <child link="wrist_camera_color_optical_frame"/>
  </joint>
  <link name="wrist_camera_color_optical_frame"/>
  <joint name="wrist_camera_usb_plug_joint" type="fixed">
    <origin rpy="3.141592653589793 0 0" xyz="-0.01238 0.012000000000000002 0"/>
    <parent link="wrist_camera_link"/>
    <child link="wrist_camera_usb_plug_link"/>
  </joint>
  <link name="wrist_camera_usb_plug_link">
    <visual>
      <!-- 0.044850 0.008000 0.018500 -->
      <origin rpy="0 0 1.5707963267948966" xyz="0. -0.022425 0."/>
      <geometry>
        <!--box size="0.044850 0.008 0.0185" /-->
        <mesh filename="package://steve_description/meshes/realsense/d405/plug.stl"/>
      </geometry>
      <material name="plastic"/>
    </visual>
    <collision>
      <origin rpy="0 0 1.5707963267948966" xyz="0. -0.022425 0."/>
      <geometry>
        <!--box size="0.044850 0.008 0.0185" /-->
        <mesh filename="package://steve_description/meshes/realsense/d405/plug_collision.stl"/>
      </geometry>
    </collision>
  </link>
</robot>
