<?xml version="1.0"?>
<!--
	NOTES:
	Units:
		Distance: m
		Angles: rad (only option)
		Mass: kg
		Inertia: kg*m^2
		
	Notes on intertia:
		-The inertias are calculated for uniform density with weights that may or may not be accurate.
		At the time of this writing only the thumb flexor weight is correct. The palm is a 'best guess' 
		approximation and the fingers are likely off by an order of magnitude
	
	Notes on finger q2:
		-The hand is a 4 bar linkage mechanism forming an 'X'. 4 bar linkages are not supported in the 
		urdf format. The motion of the second finger joint is fully defined by the motion of the first 
		finger joint. The calculation to find the index finger second joint angle given the first is provided
		in a matlab script elsewhere in this repository.
-->
<robot xmlns:xacro="http://www.ros.org/wiki/xacro" name="ability_hand">
<xacro:macro name="ability_hand" params="parent gazebo">

	<!-- ****************************************************************** -->
	<!-- ====================== ABILITY HAND ============================== -->
	<!-- ****************************************************************** -->

	<xacro:property name="ns" value="" />
	
	<xacro:macro name="mimic_joint_plugin_gazebo" params="name_prefix parent_joint mimic_joint has_pid:=false multiplier:=1.0 offset:=0 sensitiveness:=0.0 max_effort:=1.0">
		<gazebo>
			<plugin name="${name_prefix}mimic_joint_plugin" filename="libroboticsgroup_upatras_gazebo_mimic_joint_plugin.so">
				<joint>${parent_joint}</joint>
				<mimicJoint>${mimic_joint}</mimicJoint>
				<xacro:if value="${has_pid}">                     <!-- if set to true, PID parameters from "/gazebo_ros_control/pid_gains/${mimic_joint}" are loaded -->
					<hasPID />
				</xacro:if>
				<multiplier>${multiplier}</multiplier>
				<offset>${offset}</offset>
				<sensitiveness>${sensitiveness}</sensitiveness>   <!-- if absolute difference between setpoint and process value is below this threshold, do nothing; 0.0 = disable [rad] -->
				<maxEffort>${max_effort}</maxEffort>              <!-- only taken into account if has_pid:=true [Nm] -->
				<xacro:unless value="${ns == ''}">
					<robotNamespace>${ns}</robotNamespace>
				</xacro:unless>
			</plugin>
		</gazebo>
	</xacro:macro>

	<joint name="${parent}_hand_joint" type="fixed">
		<parent link="${parent}" />
		<child link="hand_mount" />
		<origin xyz="0.0 0.0 0.0" rpy="${pi/2} 0.0 ${pi}" />
	</joint>

	<xacro:property name="hand_mount_mass" value="0.2" />

	<xacro:macro name="default_inertial" params="mass">
		<inertial>
			<mass value="${mass}" />
			<inertia ixx="1.0" ixy="0.0" ixz="0.0"
						iyy="1.0" iyz="0.0"
						izz="1.0" />
		</inertial>
	</xacro:macro>

	<!-- define materials -->
	<material name="white">
		<color rgba="1 1 1 1"/>
	</material>
	<material name="black">
		<color rgba="0.2 0.2 0.2 1"/>
	</material>

	<link name="hand_mount">
		<visual>
			<origin rpy = "0 0 0" xyz = "0 0 0"/>
			<geometry>
				<mesh filename="package://steve_description/meshes/ability_hand/Psyonic_UR5_Inline.STL" scale="0.001 0.001 0.001"/>
			</geometry>
			<material name="white" />
		</visual>
		<collision>
			<origin rpy = "0 0 0" xyz = "0 0 0"/>
			<geometry>
				<mesh filename="package://steve_description/meshes/ability_hand/Psyonic_UR5_Inline_lowpoly.STL" scale="0.001 0.001 0.001"/>
			</geometry>
		</collision>
		<xacro:default_inertial mass="${hand_mount_mass}" />
	</link>

	<joint name="hand_mount_joint" type="fixed">
		<parent link="hand_mount" />
		<child link="hand_base" />
		<origin xyz="0.0 0.02 0.0" rpy="${-pi/2} 0.0 0.0" />
	</joint>

	<link name="hand_base">
		<visual name="wrist_mesh">
			<origin rpy = "0 0 0" xyz = "0 0 0"/>
			<geometry>
				<mesh filename="package://steve_description/meshes/ability_hand/wristmesh.STL"/>
			</geometry>
			<material name="black" />
		</visual>
		<collision>
			<origin rpy = "0 0 0" xyz = "0 0 0"/>
			<geometry>
				<mesh filename="package://steve_description/meshes/ability_hand/wristmesh.STL"/>
			</geometry>
		</collision>
		<xacro:default_inertial mass="0.2" />
	</link>

	<joint name="wrist2thumb" type="fixed">
		<parent link="hand_base"/>
		<child link="thumb_base"/>
		<origin xyz = "-24.0476665e-3 3.78124745e-3 32.32964923e-3" rpy = "3.14148426 -0.08848813 -3.14036612"/>
	</joint>
  
	<link name="thumb_base" >
		<xacro:default_inertial mass="0.2" />
		<visual name="palm_mesh">
			<origin rpy = "0 0 0" xyz = "0 0 0"/>
			<geometry>
				<mesh filename="package://steve_description/meshes/ability_hand/FB_palm_ref_MIR.STL"/>
			</geometry>
			<material name="black" />
		</visual>
		<collision>
			<origin rpy = "0 0 0" xyz = "0 0 0"/>
			<geometry>
				<mesh filename="package://steve_description/meshes/ability_hand/FB_palm_ref_MIR.STL"/>
			</geometry>
		</collision>
	</link>

	<link name="index_L1" >
		<inertial>
			<mass value = "0.00635888"/>
			<inertia ixx="0.29766e-6" ixy = "-0.06447133e-6" ixz = "-0.00423315e-6" iyy = "3.6947967e-6" iyz = "0.00083028e-6" izz = "3.8176336e-6" />
			<origin xyz = "22.41911e-3 -0.15798201e-3 -0.01319866e-3" rpy = "0 0 0"/>
		</inertial>
		<visual name="index_mesh_1">
			<origin rpy = "0 0 0" xyz = "0 0 0"/>
			<geometry>
				<mesh filename="package://steve_description/meshes/ability_hand/idx-F1.STL"/>
			</geometry>
			<material name="black" />
		</visual>
		<collision>
			<origin rpy = "0 0 0" xyz = "0 0 0"/>
			<geometry>
				<mesh filename="package://steve_description/meshes/ability_hand/idx-F1.STL"/>
			</geometry>
		</collision>
	</link>

	<link name="index_L2" >
		<inertial>
			<mass value = "0.00645"/>
			<inertia ixx="0.82671e-6" ixy = "-1.08876e-6" ixz = "-0.00037e-6" iyy = "1.98028e-6" iyz = "0.00081e-6" izz = "2.64638e-6" />
			<origin rpy = "0 0 0" xyz = "13.36818e-3 -8.75392e-3 -0.02886e-3"/>
		</inertial>		
		<visual name="index_mesh_2">
			<origin rpy = "0 0 0" xyz = "0 0 0"/>
			<geometry>
				<mesh filename="package://steve_description/meshes/ability_hand/idx-F2-Lg-2.STL"/>
			</geometry>
			<material name="black" />
		</visual>
		<collision>
			<origin rpy = "0 0 0" xyz = "0 0 0"/>
			<geometry>
				<mesh filename="package://steve_description/meshes/ability_hand/idx-F2-Lg-2.STL"/>
			</geometry>
		</collision>
	</link>

	<joint name="index_joint" type="revolute">
		<parent link="thumb_base"/>
		<child link="index_L1"/>
		<origin xyz = " 9.49e-3 -13.04e-3 -62.95e-3 " rpy = " -1.1595426535897932 1.284473 -1.0510016535897932 " />
		<axis xyz="0 0 1"/>
		<limit lower = "0" upper = "2.0943951" effort = "6.0" velocity = "8.0677777442"/>		<!-- angles in rad, efforts in N-m, velocity in rad/s -->
		<dynamics damping = "0.001" friction = "0.001" />	<!-- Friction coefficient is not from quantitative measurement -->
	</joint>
	

	<joint name="index_mimic_joint" type="revolute">
		<parent link="index_L1"/>
		<child link="index_L2"/>
		<origin xyz = "38.472723e-3 3.257695e-3 0.000000e-3" rpy = "0 0 0"/>
		<axis xyz="0 0 1"/>
		<limit lower = "0.0" upper = "2.6586" effort = "6.0" velocity = "8.0677777442"/>		<!-- angles in rad, efforts in N-m, velocity in rad/s -->
		<dynamics damping = "0.001" friction = "0.001" />	<!-- Friction coefficient is not from quantitative measurement -->
		<mimic joint = "index_joint" multiplier =  "1.05851325" offset = "0.2"/>
	</joint>

	<xacro:if value="${gazebo}">
		<xacro:mimic_joint_plugin_gazebo name_prefix="imj" 
				parent_joint="index_joint" mimic_joint="index_mimic_joint" 
				has_pid="false" multiplier="1.05851325" offset = "0.2" />
	</xacro:if>

	<link name="index_anchor"/>

	<joint name="idx_anchor" type="fixed">
		<parent link = "index_L2"/>
		<child link = "index_anchor"/>
		<origin rpy = "0 0 0" xyz = "31.5541e-3  -10.44e-3 0.14e-3"/>
	</joint>

	<link name="middle_L1" >
		<inertial>
			<mass value = "0.00635888"/>
			<inertia ixx="0.29766e-6" ixy = "-0.06447133e-6" ixz = "-0.00423315e-6" iyy = "3.6947967e-6" iyz = "0.00083028e-6" izz = "3.8176336e-6" />
			<origin xyz = "22.41911e-3 -0.15798201e-3 -0.01319866e-3" rpy = "0 0 0"/>
		</inertial>
		
		<visual name="middle_mesh_1">
			<origin rpy = "0 0 0" xyz = "0 0 0"/>
			<geometry>
				<mesh filename="package://steve_description/meshes/ability_hand/idx-F1.STL"/>
			</geometry>
			<material name="black" />
		</visual>

		<collision>
			<origin rpy = "0 0 0" xyz = "0 0 0"/>
			<geometry>
				<mesh filename="package://steve_description/meshes/ability_hand/idx-F1.STL"/>
			</geometry>
		</collision>
	</link>

	<link name="middle_L2" >
		<inertial>
			<mass value = "0.00645"/>
			<inertia ixx="0.82671e-6" ixy = "-1.08876e-6" ixz = "-0.00037e-6" iyy = "1.98028e-6" iyz = "0.00081e-6" izz = "2.64638e-6" />
			<origin rpy = "0 0 0" xyz = "13.36818e-3 -8.75392e-3 -0.02886e-3"/>
		</inertial>
		<visual name="middle_mesh_2">
			<origin rpy = "0 0 0" xyz = "0 0 0"/>
			<geometry>
				<mesh filename="package://steve_description/meshes/ability_hand/idx-F2-Lg-2.STL"/>
			</geometry>
			<material name="black" />
		</visual>
		<collision>
			<origin rpy = "0 0 0" xyz = "0 0 0"/>
			<geometry>
				<mesh filename="package://steve_description/meshes/ability_hand/idx-F2-Lg-2.STL"/>
			</geometry>
		</collision>
	</link>

	<joint name="middle_joint" type="revolute">
		<parent link="thumb_base"/>
		<child link="middle_L1"/>
		<origin xyz = " -9.653191e-3 -15.310271e-3 -67.853949e-3 " rpy = " -1.2810616535897934 1.308458 -1.2453756535897933 " />
		<limit lower = "0" upper = "2.0943951" effort = "6.0" velocity = "8.0677777442"/>		<!-- angles in rad, efforts in N-m, velocity in rad/s -->
		<dynamics damping = "0.001" friction = "0.001" />	<!-- Friction coefficient is not from quantitative measurement -->
		<axis xyz="0 0 1"/>
	</joint>

	<joint name="middle_mimic_joint" type="revolute">
		<parent link="middle_L1"/>
		<child link="middle_L2"/>
		<origin xyz = "38.472723e-3 3.257695e-3 0.000000" rpy = "0 0 0"/>
		<axis xyz="0 0 1"/>
		<limit lower = "0.0" upper = "2.6586" effort = "6.0" velocity = "8.0677777442"/>		<!-- angles in rad, efforts in N-m, velocity in rad/s -->
		<dynamics damping = "0.001" friction = "0.001" />	<!-- Friction coefficient is not from quantitative measurement -->
		<mimic joint = "middle_joint" multiplier =  "1.05851325" offset = "0.2"/>
	</joint>

	<xacro:if value="${gazebo}">
		<xacro:mimic_joint_plugin_gazebo name_prefix="middle_mimic_joint" 
				parent_joint="middle_joint" mimic_joint="middle_mimic_joint" 
				has_pid="false" multiplier="1.05851325" offset = "0.2"/>
	</xacro:if>

	<link name="middle_anchor"/>

	<joint name="mid_anchor" type="fixed">
		<parent link = "middle_L2"/>
		<child link = "middle_anchor"/>
		<origin rpy = "0 0 0" xyz = "31.5541e-3  -10.44e-3 0.14e-3"/>
	</joint>

	<link name="ring_L1" >
		<inertial>
			<mass value = "0.00635888"/>
			<inertia ixx="0.29766e-6" ixy = "-0.06447133e-6" ixz = "-0.00423315e-6" iyy = "3.6947967e-6" iyz = "0.00083028e-6" izz = "3.8176336e-6" />
			<origin xyz = "22.41911e-3 -0.15798201e-3 -0.01319866e-3" rpy = "0 0 0"/>
		</inertial>
		<visual name="ring_mesh_1">
			<origin rpy = "0 0 0" xyz = "0 0 0"/>
			<geometry>
				<mesh filename="package://steve_description/meshes/ability_hand/idx-F1.STL"/>
			</geometry>
			<material name="black" />
		</visual>
		<collision>
			<origin rpy = "0 0 0" xyz = "0 0 0"/>
			<geometry>
				<mesh filename="package://steve_description/meshes/ability_hand/idx-F1.STL"/>
			</geometry>
		</collision>
	</link>

	<link name="ring_L2" >
		<inertial>
			<mass value = "0.00645"/>
			<inertia ixx="0.82671e-6" ixy = "-1.08876e-6" ixz = "-0.00037e-6" iyy = "1.98028e-6" iyz = "0.00081e-6" izz = "2.64638e-6" />
			<origin rpy = "0 0 0" xyz = "13.36818e-3 -8.75392e-3 -0.02886e-3"/>
		</inertial>
		<visual name="ring_mesh_2">
			<origin rpy = "0 0 0" xyz = "0 0 0"/>
			<geometry>
				<mesh filename="package://steve_description/meshes/ability_hand/idx-F2-Lg-2.STL"/>
			</geometry>
			<material name="black" />
		</visual>
		<collision>
			<origin rpy = "0 0 0" xyz = "0 0 0"/>
			<geometry>
				<mesh filename="package://steve_description/meshes/ability_hand/idx-F2-Lg-2.STL"/>
			</geometry>
		</collision>
	</link>

	<joint name="ring_joint" type="revolute">
		<parent link="thumb_base"/>
		<child link="ring_L1"/>
		<origin xyz = " -29.95426e-3 -14.212492e-3 -67.286105e-3 " rpy = " -1.424994653589793 1.321452 -1.4657306535897934 " />
		<limit lower = "0" upper = "2.0943951" effort = "6.0" velocity = "8.0677777442"/>		<!-- angles in rad, efforts in N-m, velocity in rad/s -->
		<dynamics damping = "0.001" friction = "0.001" />	<!-- Friction coefficient is not from quantitative measurement -->
		<axis xyz="0 0 1"/>
	</joint>

	<joint name="ring_mimic_joint" type="revolute">
		<parent link="ring_L1"/>
		<child link="ring_L2"/>
		<origin xyz = "38.472723e-3 3.257695e-3 0.000000" rpy = "0 0 0"/>
		<axis xyz="0 0 1"/>
		<limit lower = "0.0" upper = "2.6586" effort = "6.0" velocity = "8.0677777442"/>		<!-- angles in rad, efforts in N-m, velocity in rad/s -->
		<dynamics damping = "0.001" friction = "0.001" />	<!-- Friction coefficient is not from quantitative measurement -->
		<mimic joint = "ring_joint" multiplier =  "1.05851325" offset = "0.2"/>
	</joint>

	<xacro:if value="${gazebo}">
		<xacro:mimic_joint_plugin_gazebo name_prefix="ring_mimic_joint" 
				parent_joint="ring_joint" mimic_joint="ring_mimic_joint" 
				has_pid="false" multiplier="1.05851325" offset = "0.2"/>
	</xacro:if>

	<link name="ring_anchor"/>

	<joint name="rng_anchor" type="fixed">
		<parent link = "ring_L2"/>
		<child link = "ring_anchor"/>
		<origin rpy = "0 0 0" xyz = "31.5541e-3  -10.44e-3 0.14e-3"/>
	</joint>

	<link name="pinky_L1" >
		<inertial>
			<mass value = "0.00635888"/>
			<inertia ixx="0.29766e-6" ixy = "-0.06447133e-6" ixz = "-0.00423315e-6" iyy = "3.6947967e-6" iyz = "0.00083028e-6" izz = "3.8176336e-6" />
			<origin xyz = "22.41911e-3 -0.15798201e-3 -0.01319866e-3" rpy = "0 0 0"/>
		</inertial>
		<visual name="pinky_mesh_1">
			<origin rpy = "0 0 0" xyz = "0 0 0"/>
			<geometry>
				<mesh filename="package://steve_description/meshes/ability_hand/idx-F1.STL"/>
			</geometry>
			<material name="black" />
		</visual>
		<collision>
			<origin rpy = "0 0 0" xyz = "0 0 0"/>
			<geometry>
				<mesh filename="package://steve_description/meshes/ability_hand/idx-F1.STL"/>
			</geometry>
		</collision>
	</link>

	<link name="pinky_L2" >
		<inertial>
			<mass value = "0.00645"/>
			<inertia ixx="0.82671e-6" ixy = "-1.08876e-6" ixz = "-0.00037e-6" iyy = "1.98028e-6" iyz = "0.00081e-6" izz = "2.64638e-6" />
			<origin rpy = "0 0 0" xyz = "13.36818e-3 -8.75392e-3 -0.02886e-3"/>
		</inertial>
		<visual name="pinky_mesh_2">
			<origin rpy = "0 0 0" xyz = "0 0 0"/>
			<geometry>
				<mesh filename="package://steve_description/meshes/ability_hand/idx-F2-Lg-2.STL"/>
			</geometry>
			<material name="black" />
		</visual>
		<collision>
			<origin rpy = "0 0 0" xyz = "0 0 0"/>
			<geometry>
				<mesh filename="package://steve_description/meshes/ability_hand/idx-F2-Lg-2.STL"/>
			</geometry>
		</collision>
	</link>

	<joint name="pinky_joint" type="revolute">
		<parent link="thumb_base"/>
		<child link="pinky_L1"/>
		<origin xyz = " -49.521293e-3 -11.004583e-3 -63.029065e-3 " rpy = " -1.3764826535897934 1.32222 -1.4832096535897932 " />
		<limit lower = "0" upper = "2.0943951" effort = "4.0" velocity = "8.0677777442"/>		<!-- angles in rad, efforts in N-m, velocity in rad/s -->
		<dynamics damping = "0.001" friction = "0.001" />	<!-- Friction coefficient is not from quantitative measurement -->
		<axis xyz="0 0 1"/>
	</joint>

	<joint name="pinky_mimic_joint" type="revolute">
		<parent link="pinky_L1"/>
		<child link="pinky_L2"/>
		<origin xyz = "38.472723e-3 3.257695e-3 0.000000" rpy = "0 0 0"/>
		<limit lower = "0.0" upper = "2.6586" effort = "4.0" velocity = "8.0677777442"/>		<!-- angles in rad, efforts in N-m, velocity in rad/s -->
		<dynamics damping = "0.001" friction = "0.001" />	<!-- Friction coefficient is not from quantitative measurement -->
		<axis xyz="0 0 1"/>
		<mimic joint = "pinky_joint" multiplier =  "1.05851325" offset = "0.2"/>
	</joint>

	<xacro:if value="${gazebo}">
		<xacro:mimic_joint_plugin_gazebo name_prefix="pinky_mimic_joint" 
				parent_joint="pinky_joint" mimic_joint="pinky_mimic_joint" 
				has_pid="false" multiplier="1.05851325" offset = "0.2"/>
	</xacro:if>

	<link name="pinky_anchor"/>

	<joint name="pnky_anchor" type="fixed">
		<parent link = "pinky_L2"/>
		<child link = "pinky_anchor"/>
		<origin rpy = "0 0 0" xyz = "31.5541e-3  -10.44e-3 0.14e-3"/>
	</joint>

	<link name="thumb_L1" >
		<xacro:default_inertial mass="0.002" />
		<visual name="thumb_mesh_1">
			<origin rpy = "0 0 0" xyz = "0 0 0"/>
			<geometry>
				<mesh filename="package://steve_description/meshes/ability_hand/thumb-F1-MIR.STL"/>
			</geometry>
			<material name="black" />
		</visual>
		<collision>
			<origin rpy = "0 0 0" xyz = "0 0 0"/>
			<geometry>
				<mesh filename="package://steve_description/meshes/ability_hand/thumb-F1-MIR.STL"/>
			</geometry>
		</collision>
	</link>

	<link name="thumb_L2" >
		<xacro:default_inertial mass="0.002" />
		<visual name="thumb_mesh_2">
			<origin rpy = "0 0 0" xyz = "0 0 0"/>
			<geometry>
				<mesh filename="package://steve_description/meshes/ability_hand/thumb-F2-right.STL"/>
			</geometry>
			<material name="black" />
		</visual>
		<collision>
			<origin rpy = "0 0 0" xyz = "0 0 0"/>
			<geometry>
				<mesh filename="package://steve_description/meshes/ability_hand/thumb-F2-right.STL"/>
			</geometry>
		</collision>
	</link>

	<joint name="thumb1_joint" type="revolute">
		<parent link="thumb_base"/>
		<child link="thumb_L1"/>
		<origin xyz = " 0.0 0.0 0.0 " rpy = " 3.141592653589793 -0.0 -0.18884434641020664 " />
		<axis xyz="0 0 1"/>
		<limit lower = "-2.0943951" upper = "0" effort = "1.2" velocity = "40.338888721"/>		<!-- angles in rad, efforts in N-m, velocity in rad/s -->
		<dynamics damping = "0.001" friction = "0.001" />	<!-- Friction coefficient is not from quantitative measurement -->
	</joint>

	<joint name="thumb2_joint" type="revolute">
		<parent link="thumb_L1"/>
		<child link="thumb_L2"/>
		<origin xyz = " 27.8283501e-3 1.7436510745838653e-19 14.7507e-3 " rpy = " 1.832595714594045 -0.0 5.366520605522463e-18 " />
		<axis xyz="0 0 1"/>
		<limit lower = "0" upper = "2.0943951" effort = "6.0" velocity = "8.0677777442"/>		<!-- angles in rad, efforts in N-m, velocity in rad/s -->
		<dynamics damping = "0.001" friction = "0.001" />	<!-- Friction coefficient is not from quantitative measurement -->		
	</joint>

	<link name="thumb_anchor"/>

	<joint name="thmb_anchor" type="fixed">
		<parent link = "thumb_L2"/>
		<child link = "thumb_anchor"/>
		<origin rpy = "0 0 0" xyz = "52.00122724e-3 28.00869333e-3 6.98483578e-3"/>
	</joint>

	<sensor name="fsr1">
		<parent link = "index_L2"/>
		<origin xyz = "[ 0.03678129 -0.01966348  0.        ]" rpy = "[-1.57079633  1.11908681 -1.57079633]"/>
	</sensor>

	<sensor name="fsr2">
		<parent link = "index_L2"/>
		<origin xyz = "[ 0.03087755 -0.01531625  0.        ]" rpy = "[ 1.57079633 -0.25241514  1.57079633]"/>
	</sensor>

	<sensor name="fsr3">
		<parent link = "index_L2"/>
		<origin xyz = "[ 0.03118107 -0.01775288  0.004     ]" rpy = "[-1.57079633  0.51757639 -1.57079633]"/>
	</sensor>

	<sensor name="fsr4">
		<parent link = "index_L2"/>
		<origin xyz = "[ 0.01680497 -0.01308243  0.004     ]" rpy = "[-1.57079633  0.66148388 -1.57079633]"/>
	</sensor>

	<sensor name="fsr5">
		<parent link = "index_L2"/>
		<origin xyz = "[ 0.03118107 -0.01775288 -0.004     ]" rpy = "[-1.57079633  0.51757639 -1.57079633]"/>
	</sensor>

	<sensor name="fsr6">
		<parent link = "index_L2"/>
		<origin xyz = "[ 0.01680497 -0.01308243 -0.004     ]" rpy = "[-1.57079633  0.66148388 -1.57079633]"/>
	</sensor>

	<sensor name="fsr7">
		<parent link = "middle_L2"/>
		<origin xyz = "[ 0.03678129 -0.01966348  0.        ]" rpy = "[-1.57079633  1.11908681 -1.57079633]"/>
	</sensor>

	<sensor name="fsr8">
		<parent link = "middle_L2"/>
		<origin xyz = "[ 0.03087755 -0.01531625  0.        ]" rpy = "[ 1.57079633 -0.25241514  1.57079633]"/>
	</sensor>

	<sensor name="fsr9">
		<parent link = "middle_L2"/>
		<origin xyz = "[ 0.03118107 -0.01775288  0.004     ]" rpy = "[-1.57079633  0.51757639 -1.57079633]"/>
	</sensor>

	<sensor name="fsr10">
		<parent link = "middle_L2"/>
		<origin xyz = "[ 0.01680497 -0.01308243  0.004     ]" rpy = "[-1.57079633  0.66148388 -1.57079633]"/>
	</sensor>

	<sensor name="fsr11">
		<parent link = "middle_L2"/>
		<origin xyz = "[ 0.03118107 -0.01775288 -0.004     ]" rpy = "[-1.57079633  0.51757639 -1.57079633]"/>
	</sensor>

	<sensor name="fsr12">
		<parent link = "middle_L2"/>
		<origin xyz = "[ 0.01680497 -0.01308243 -0.004     ]" rpy = "[-1.57079633  0.66148388 -1.57079633]"/>
	</sensor>

	<sensor name="fsr13">
		<parent link = "ring_L2"/>
		<origin xyz = "[ 0.03678129 -0.01966348  0.        ]" rpy = "[-1.57079633  1.11908681 -1.57079633]"/>
	</sensor>

	<sensor name="fsr14">
		<parent link = "ring_L2"/>
		<origin xyz = "[ 0.03087755 -0.01531625  0.        ]" rpy = "[ 1.57079633 -0.25241514  1.57079633]"/>
	</sensor>

	<sensor name="fsr15">
		<parent link = "ring_L2"/>
		<origin xyz = "[ 0.03118107 -0.01775288  0.004     ]" rpy = "[-1.57079633  0.51757639 -1.57079633]"/>
	</sensor>

	<sensor name="fsr16">
		<parent link = "ring_L2"/>
		<origin xyz = "[ 0.01680497 -0.01308243  0.004     ]" rpy = "[-1.57079633  0.66148388 -1.57079633]"/>
	</sensor>

	<sensor name="fsr17">
		<parent link = "ring_L2"/>
		<origin xyz = "[ 0.03118107 -0.01775288 -0.004     ]" rpy = "[-1.57079633  0.51757639 -1.57079633]"/>
	</sensor>

	<sensor name="fsr18">
		<parent link = "ring_L2"/>
		<origin xyz = "[ 0.01680497 -0.01308243 -0.004     ]" rpy = "[-1.57079633  0.66148388 -1.57079633]"/>
	</sensor>

	<sensor name="fsr19">
		<parent link = "pinky_L2"/>
		<origin xyz = "[ 0.03678129 -0.01966348  0.        ]" rpy = "[-1.57079633  1.11908681 -1.57079633]"/>
	</sensor>

	<sensor name="fsr20">
		<parent link = "pinky_L2"/>
		<origin xyz = "[ 0.03087755 -0.01531625  0.        ]" rpy = "[ 1.57079633 -0.25241514  1.57079633]"/>
	</sensor>

	<sensor name="fsr21">
		<parent link = "pinky_L2"/>
		<origin xyz = "[ 0.03118107 -0.01775288  0.004     ]" rpy = "[-1.57079633  0.51757639 -1.57079633]"/>
	</sensor>

	<sensor name="fsr22">
		<parent link = "pinky_L2"/>
		<origin xyz = "[ 0.01680497 -0.01308243  0.004     ]" rpy = "[-1.57079633  0.66148388 -1.57079633]"/>
	</sensor>

	<sensor name="fsr23">
		<parent link = "pinky_L2"/>
		<origin xyz = "[ 0.03118107 -0.01775288 -0.004     ]" rpy = "[-1.57079633  0.51757639 -1.57079633]"/>
	</sensor>

	<sensor name="fsr24">
		<parent link = "pinky_L2"/>
		<origin xyz = "[ 0.01680497 -0.01308243 -0.004     ]" rpy = "[-1.57079633  0.66148388 -1.57079633]"/>
	</sensor>

	<sensor name="fsr25">
		<parent link = "thumb_L2"/>
		<origin xyz = "[0.055422 0.023513 0.005055]" rpy = "[-1.57079633 -0.40123853 -1.57079633]"/>
	</sensor>

	<sensor name="fsr26">
		<parent link = "thumb_L2"/>
		<origin xyz = "[0.047909 0.02312  0.005728]" rpy = "[-1.57079633 -0.44961601 -1.57079633]"/>
	</sensor>

	<sensor name="fsr27">
		<parent link = "thumb_L2"/>
		<origin xyz = "[ 0.048227  0.022352 -0.000805]" rpy = "[-1.57079633 -0.43229053 -1.57079633]"/>
	</sensor>

	<sensor name="fsr28">
		<parent link = "thumb_L2"/>
		<origin xyz = "[ 0.036868  0.017111 -0.001369]" rpy = "[nan nan nan]"/>
	</sensor>

	<sensor name="fsr29">
		<parent link = "thumb_L2"/>
		<origin xyz = "[0.049435 0.019437 0.01097 ]" rpy = "[-1.57079633 -0.44946695 -1.57079633]"/>
	</sensor>

	<sensor name="fsr30">
		<parent link = "thumb_L2"/>
		<origin xyz = "[0.038158 0.013997 0.011211]" rpy = "[nan nan nan]"/>
	</sensor>

	<!-- transmissoins -->
    <transmission name="index_joint_transmission">
      <type>transmission_interface/SimpleTransmission</type>
      <joint name="index_joint">
        <hardwareInterface>hardware_interface/PositionJointInterface</hardwareInterface>
      </joint>
      <actuator name="index_joint_motor">
        <mechanicalReduction>1.0</mechanicalReduction>
      </actuator>
    </transmission>

    <transmission name="middle_joint_transmission">
      <type>transmission_interface/SimpleTransmission</type>
      <joint name="middle_joint">
        <hardwareInterface>hardware_interface/PositionJointInterface</hardwareInterface>
      </joint>
      <actuator name="middle_joint_motor">
        <mechanicalReduction>1.0</mechanicalReduction>
      </actuator>
    </transmission>

    <transmission name="ring_joint_transmission">
      <type>transmission_interface/SimpleTransmission</type>
      <joint name="ring_joint">
        <hardwareInterface>hardware_interface/PositionJointInterface</hardwareInterface>
      </joint>
      <actuator name="ring_joint_motor">
        <mechanicalReduction>1.0</mechanicalReduction>
      </actuator>
    </transmission>

    <transmission name="pinky_joint_transmission">
      <type>transmission_interface/SimpleTransmission</type>
      <joint name="pinky_joint">
        <hardwareInterface>hardware_interface/PositionJointInterface</hardwareInterface>
      </joint>
      <actuator name="pinky_joint_motor">
        <mechanicalReduction>1.0</mechanicalReduction>
      </actuator>
    </transmission>

    <transmission name="thumb1_joint_transmission">
      <type>transmission_interface/SimpleTransmission</type>
      <joint name="thumb1_joint">
        <hardwareInterface>hardware_interface/PositionJointInterface</hardwareInterface>
      </joint>
      <actuator name="thumb1_joint_motor">
        <mechanicalReduction>1.0</mechanicalReduction>
      </actuator>
    </transmission>

    <transmission name="thumb2_joint_transmission">
      <type>transmission_interface/SimpleTransmission</type>
      <joint name="thumb2_joint">
        <hardwareInterface>hardware_interface/PositionJointInterface</hardwareInterface>
      </joint>
      <actuator name="thumb2_joint_motor">
        <mechanicalReduction>1.0</mechanicalReduction>
      </actuator>
    </transmission>


	<!-- gazebo self collidde -->
	<gazebo reference="hand_mount">
		<selfCollide>true</selfCollide>
	</gazebo>
	<gazebo reference="hand_base">
		<selfCollide>true</selfCollide>
	</gazebo>
	<gazebo reference="thumb_L1">
		<selfCollide>true</selfCollide>
	</gazebo>
	<gazebo reference="thumb_L2">
		<selfCollide>true</selfCollide>
	</gazebo>
	<gazebo reference="thumb_base">
		<selfCollide>true</selfCollide>
	</gazebo>
	<gazebo reference="thumb_anchor">
		<selfCollide>true</selfCollide>
	</gazebo>
	<gazebo reference="index_L1">
		<selfCollide>true</selfCollide>
	</gazebo>
	<gazebo reference="index_L2">
		<selfCollide>true</selfCollide>
	</gazebo>
	<gazebo reference="index_anchor">
		<selfCollide>true</selfCollide>
	</gazebo>
	<gazebo reference="middle_L1">
		<selfCollide>true</selfCollide>
	</gazebo>
	<gazebo reference="middle_L2">
		<selfCollide>true</selfCollide>
	</gazebo>
	<gazebo reference="middle_anchor">
		<selfCollide>true</selfCollide>
	</gazebo>
	<gazebo reference="ring_L1">
		<selfCollide>true</selfCollide>
	</gazebo>
	<gazebo reference="ring_L2">
		<selfCollide>true</selfCollide>
	</gazebo>
	<gazebo reference="ring_anchor">
		<selfCollide>true</selfCollide>
	</gazebo>
	<gazebo reference="pinky_L1">
		<selfCollide>true</selfCollide>
	</gazebo>
	<gazebo reference="pinky_L2">
		<selfCollide>true</selfCollide>
	</gazebo>
	<gazebo reference="pinky_anchor">
		<selfCollide>true</selfCollide>
	</gazebo>

</xacro:macro>
</robot>