<?xml version="1.0"?>
<robot xmlns:xacro="http://www.ros.org/wiki/xacro" name="mmo_700">

  <xacro:macro name="mmo_700_wheel" params="name parent *origin">
   
    <!-- =================== MMO_700 WHEEL =================== -->
    <link name="${name}_link" type="wheel">
      <inertial>
        <mass value="5.9" />
        <origin xyz="0 0 0" rpy="0 0 0" />
          <inertia  ixx="0.04" ixy="0.0007" ixz="0.0"
                    iyy="0.02" iyz="0.004"  izz="0.05" />
      </inertial>
      <visual>
        <origin xyz="0 0 0" rpy="0 0 0"/>
        <geometry>
          <mesh filename="package://steve_description/meshes/mmo_700/MPO-700-WHEEL.dae" scale="0.001 0.001 0.001"/>
        </geometry>
      </visual>
      <collision>
        <origin xyz="0 0 0" rpy="0 0 0" />
        <geometry>
          <mesh filename="package://steve_description/meshes/mmo_700/MPO-700-WHEEL.dae" scale="0.001 0.001 0.001"/>
        </geometry>
      </collision>
    </link>

    <joint name="${name}_joint" type="continuous">
      <xacro:insert_block name="origin" />
      <limit effort="1000.0" lower="-1e+16" upper="1e+16" velocity="3.5"/>
      <axis xyz="1 0 0" />
      <parent link="${parent}" />
      <child link="${name}_link" />
    </joint>

    <gazebo reference="${name}_link">
      <mu1 value="0.05"/>
      <mu2 value="0.05"/>
      <kp value="100000.0" />
      <kd value="10.0" />
    </gazebo>

    <!-- Add transmission for the wheel joint -->
    <transmission name="${name}_transmission">
      <type>transmission_interface/SimpleTransmission</type>
      <joint name="${name}_joint">
        <hardwareInterface>hardware_interface/VelocityJointInterface</hardwareInterface>
      </joint>
      <actuator name="${name}_motor">
        <mechanicalReduction>1</mechanicalReduction>
      </actuator>
    </transmission>


  </xacro:macro>
</robot>


