<?xml version="1.0"?>
<robot xmlns:xacro="http://www.ros.org/wiki/xacro" name="ur5e_robot_arm">
    
    <xacro:macro name="ur5e" params="parent *origin tf_prefix visual_mesh_path collision_mesh_path">
        
        <!-- ***************************************************************************** -->
        <!-- ===================================== UR5E ================================== -->
        <!-- ***************************************************************************** -->

        <!-- ur5e links -->
        <link name="${tf_prefix}_base_link"/>
        <link name="${tf_prefix}_base_link_inertia">
            <visual>
            <origin rpy="0 0 3.141592653589793" xyz="0 0 0"/>
            <geometry>
                <mesh filename="${visual_mesh_path}/base.dae"/>
            </geometry>
            </visual>
            <collision>
            <origin rpy="0 0 3.141592653589793" xyz="0 0 0"/>
            <geometry>
                <mesh filename="${collision_mesh_path}/base.stl"/>
            </geometry>
            </collision>
            <inertial>
            <mass value="4.0"/>
            <origin rpy="0 0 0" xyz="0 0 0"/>
            <inertia ixx="0.00443333156" ixy="0.0" ixz="0.0" iyy="0.00443333156" iyz="0.0" izz="0.0072"/>
            </inertial>
        </link>
        <link name="${tf_prefix}_shoulder_link">
            <visual>
            <origin rpy="0 0 3.141592653589793" xyz="0 0 0"/>
            <geometry>
                <mesh filename="${visual_mesh_path}/shoulder.dae"/>
            </geometry>
            </visual>
            <collision>
            <origin rpy="0 0 3.141592653589793" xyz="0 0 0"/>
            <geometry>
                <mesh filename="${collision_mesh_path}/shoulder.stl"/>
            </geometry>
            </collision>
            <inertial>
            <mass value="3.761"/>
            <origin rpy="0 0 0" xyz="0.0 -0.00193 -0.02561"/>
            <inertia ixx="0.010267499999999999" ixy="0" ixz="0" iyy="0.010267499999999999" iyz="0" izz="0.00666"/>
            </inertial>
        </link>
        <link name="${tf_prefix}_upper_arm_link">
            <visual>
            <origin rpy="1.5707963267948966 0 -1.5707963267948966" xyz="0 0 0.138"/>
            <geometry>
                <mesh filename="${visual_mesh_path}/upperarm.dae"/>
            </geometry>
            </visual>
            <collision>
            <origin rpy="1.5707963267948966 0 -1.5707963267948966" xyz="0 0 0.138"/>
            <geometry>
                <mesh filename="${collision_mesh_path}/upperarm.stl"/>
            </geometry>
            </collision>
            <inertial>
            <mass value="8.058"/>
            <origin rpy="0 1.570796326794897 0" xyz="-0.2125 0.0 0.11336"/>
            <inertia ixx="0.13388583541666665" ixy="0" ixz="0" iyy="0.13388583541666665" iyz="0" izz="0.0151074"/>
            </inertial>
        </link>
        <link name="${tf_prefix}_forearm_link">
            <visual>
            <origin rpy="1.5707963267948966 0 -1.5707963267948966" xyz="0 0 0.007"/>
            <geometry>
                <mesh filename="${visual_mesh_path}/forearm.dae"/>
            </geometry>
            </visual>
            <collision>
            <origin rpy="1.5707963267948966 0 -1.5707963267948966" xyz="0 0 0.007"/>
            <geometry>
                <mesh filename="${collision_mesh_path}/forearm.stl"/>
            </geometry>
            </collision>
            <inertial>
            <mass value="2.846"/>
            <origin rpy="0 1.570796326794897 0" xyz="-0.2422 0.0 0.0265"/>
            <inertia ixx="0.03120936758333333" ixy="0" ixz="0" iyy="0.03120936758333333" iyz="0" izz="0.004095"/>
            </inertial>
        </link>
        <link name="${tf_prefix}_wrist_1_link">
            <visual>
            <origin rpy="1.5707963267948966 0 0" xyz="0 0 -0.127"/>
            <geometry>
                <mesh filename="${visual_mesh_path}/wrist1.dae"/>
            </geometry>
            </visual>
            <collision>
            <origin rpy="1.5707963267948966 0 0" xyz="0 0 -0.127"/>
            <geometry>
                <mesh filename="${collision_mesh_path}/wrist1.stl"/>
            </geometry>
            </collision>
            <inertial>
            <mass value="1.37"/>
            <origin rpy="0 0 0" xyz="0.0 -0.01634 -0.0018"/>
            <inertia ixx="0.0025599" ixy="0" ixz="0" iyy="0.0025599" iyz="0" izz="0.0021942"/>
            </inertial>
        </link>
        <link name="${tf_prefix}_wrist_2_link">
            <visual>
            <origin rpy="0 0 0" xyz="0 0 -0.0997"/>
            <geometry>
                <mesh filename="${visual_mesh_path}/wrist2.dae"/>
            </geometry>
            </visual>
            <collision>
            <origin rpy="0 0 0" xyz="0 0 -0.0997"/>
            <geometry>
                <mesh filename="${collision_mesh_path}/wrist2.stl"/>
            </geometry>
            </collision>
            <inertial>
            <mass value="1.3"/>
            <origin rpy="0 0 0" xyz="0.0 0.01634 -0.0018"/>
            <inertia ixx="0.0025599" ixy="0" ixz="0" iyy="0.0025599" iyz="0" izz="0.0021942"/>
            </inertial>
        </link>
        <link name="${tf_prefix}_wrist_3_link">
            <visual>
            <origin rpy="1.5707963267948966 0 0" xyz="0 0 -0.0989"/>
            <geometry>
                <mesh filename="${visual_mesh_path}/wrist3.dae"/>
            </geometry>
            </visual>
            <collision>
            <origin rpy="1.5707963267948966 0 0" xyz="0 0 -0.0989"/>
            <geometry>
                <mesh filename="${collision_mesh_path}/wrist3.stl"/>
            </geometry>
            </collision>
            <inertial>
            <mass value="0.365"/>
            <origin rpy="0 0 0" xyz="0.0 0.0 -0.001159"/>
            <inertia ixx="9.890414008333333e-05" ixy="0" ixz="0" iyy="9.890414008333333e-05" iyz="0" izz="0.0001321171875"/>
            </inertial>
        </link>
        
        <!-- ur5e joints -->
        <joint name="${tf_prefix}_base_joint" type="fixed">
            <xacro:insert_block name="origin" />
            <!-- <origin rpy="3.141592653589793/2 3.141592653589793/2 0" xyz="0 0 0"/> -->
            <parent link="${parent}"/>
            <child link="${tf_prefix}_base_link"/>
        </joint>
        <joint name="${tf_prefix}_base_link-base_link_inertia" type="fixed">
            <parent link="${tf_prefix}_base_link"/>
            <child link="${tf_prefix}_base_link_inertia"/>
            <!-- 'base_link' is REP-103 aligned (so X+ forward), while the internal
                frames of the robot/controller have X+ pointing backwards.
                Use the joint between 'base_link' and 'base_link_inertia' (a dummy
                link/frame) to introduce the necessary rotation over Z (of pi rad).
            -->
            <origin rpy="0 0 3.141592653589793" xyz="0 0 0"/>
        </joint>
        <joint name="${tf_prefix}_shoulder_pan_joint" type="revolute">
            <parent link="${tf_prefix}_base_link_inertia"/>
            <child link="${tf_prefix}_shoulder_link"/>
            <origin rpy="0 0 0" xyz="0 0 0.1625"/>
            <axis xyz="0 0 1"/>
            <limit effort="150.0" lower="-6.283185307179586" upper="6.283185307179586" velocity="3.141592653589793"/>
            <dynamics damping="0" friction="0"/>
        </joint>
        <joint name="${tf_prefix}_shoulder_lift_joint" type="revolute">
            <parent link="${tf_prefix}_shoulder_link"/>
            <child link="${tf_prefix}_upper_arm_link"/>
            <origin rpy="1.570796327 0 0" xyz="0 0 0"/>
            <axis xyz="0 0 1"/>
            <limit effort="150.0" lower="-6.283185307179586" upper="6.283185307179586" velocity="3.141592653589793"/>
            <dynamics damping="0" friction="0"/>
        </joint>
        <joint name="${tf_prefix}_elbow_joint" type="revolute">
            <parent link="${tf_prefix}_upper_arm_link"/>
            <child link="${tf_prefix}_forearm_link"/>
            <origin rpy="0 0 0" xyz="-0.425 0 0"/>
            <axis xyz="0 0 1"/>
            <limit effort="150.0" lower="-3.141592653589793" upper="3.141592653589793" velocity="3.141592653589793"/>
            <dynamics damping="0" friction="0"/>
        </joint>
        <joint name="${tf_prefix}_wrist_1_joint" type="revolute">
            <parent link="${tf_prefix}_forearm_link"/>
            <child link="${tf_prefix}_wrist_1_link"/>
            <origin rpy="0 0 0" xyz="-0.3922 0 0.1333"/>
            <axis xyz="0 0 1"/>
            <limit effort="28.0" lower="-6.283185307179586" upper="6.283185307179586" velocity="3.141592653589793"/>
            <dynamics damping="0" friction="0"/>
        </joint>
        <joint name="${tf_prefix}_wrist_2_joint" type="revolute">
            <parent link="${tf_prefix}_wrist_1_link"/>
            <child link="${tf_prefix}_wrist_2_link"/>
            <origin rpy="1.570796327 0 0" xyz="0 -0.0997 -2.044881182297852e-11"/>
            <axis xyz="0 0 1"/>
            <limit effort="28.0" lower="-6.283185307179586" upper="6.283185307179586" velocity="3.141592653589793"/>
            <dynamics damping="0" friction="0"/>
        </joint>
        <joint name="${tf_prefix}_wrist_3_joint" type="revolute">
            <parent link="${tf_prefix}_wrist_2_link"/>
            <child link="${tf_prefix}_wrist_3_link"/>
            <origin rpy="1.570796326589793 3.141592653589793 3.141592653589793" xyz="0 0.0996 -2.042830148012698e-11"/>
            <axis xyz="0 0 1"/>
            <limit effort="28.0" lower="-6.283185307179586" upper="6.283185307179586" velocity="3.141592653589793"/>
            <dynamics damping="0" friction="0"/>
        </joint>
        <link name="${tf_prefix}_ft_frame"/>
        <joint name="${tf_prefix}_wrist_3_link-ft_frame" type="fixed">
            <parent link="${tf_prefix}_wrist_3_link"/>
            <child link="${tf_prefix}_ft_frame"/>
            <origin rpy="3.141592653589793 0 0" xyz="0 0 0"/>
        </joint>

        <!-- ROS-Industrial 'base' frame - base_link to UR 'Base' Coordinates transform -->
        <link name="${tf_prefix}_base"/>
        <joint name="${tf_prefix}_base_link-base_fixed_joint" type="fixed">
            <!-- Note the rotation over Z of pi radians - as base_link is REP-103
                aligned (i.e., has X+ forward, Y+ left and Z+ up), this is needed
                to correctly align 'base' with the 'Base' coordinate system of
                the UR controller.
            -->
            <origin rpy="0 0 3.141592653589793" xyz="0 0 0"/>
            <parent link="${tf_prefix}_base_link"/>
            <child link="${tf_prefix}_base"/>
        </joint>
        <!-- ROS-Industrial 'flange' frame - attachment point for EEF models -->
        <link name="${tf_prefix}_flange"/>
        <joint name="${tf_prefix}_wrist_3-flange" type="fixed">
            <parent link="${tf_prefix}_wrist_3_link"/>
            <child link="${tf_prefix}_flange"/>
            <origin rpy="0 -1.5707963267948966 -1.5707963267948966" xyz="0 0 0"/>
        </joint>
        <!-- ROS-Industrial 'tool0' frame - all-zeros tool frame -->
        <link name="${tf_prefix}_tool0"/>
        <joint name="${tf_prefix}_flange-tool0" type="fixed">
            <!-- default toolframe - X+ left, Y+ up, Z+ front -->
            <origin rpy="1.5707963267948966 0 1.5707963267948966" xyz="0 0 0"/>
            <parent link="${tf_prefix}_flange"/>
            <child link="${tf_prefix}_tool0"/>
        </joint>

        <!-- transmissions -->
        <transmission name="${tf_prefix}_shoulder_pan_transmission">
            <type>transmission_interface/SimpleTransmission</type>
            <joint name="${tf_prefix}_shoulder_pan_joint">
            <hardwareInterface>hardware_interface/VelocityJointInterface</hardwareInterface>
            </joint>
            <actuator name="${tf_prefix}_shoulder_pan_motor">
            <mechanicalReduction>1</mechanicalReduction>
            </actuator>
        </transmission>
        <transmission name="${tf_prefix}_shoulder_lift_transmission">
            <type>transmission_interface/SimpleTransmission</type>
            <joint name="${tf_prefix}_shoulder_lift_joint">
            <hardwareInterface>hardware_interface/VelocityJointInterface</hardwareInterface>
            </joint>
            <actuator name="${tf_prefix}_shoulder_lift_motor">
            <mechanicalReduction>1</mechanicalReduction>
            </actuator>
        </transmission>
        <transmission name="${tf_prefix}_elbow_transmission">
            <type>transmission_interface/SimpleTransmission</type>
            <joint name="${tf_prefix}_elbow_joint">
            <hardwareInterface>hardware_interface/VelocityJointInterface</hardwareInterface>
            </joint>
            <actuator name="${tf_prefix}_elbow_motor">
            <mechanicalReduction>1</mechanicalReduction>
            </actuator>
        </transmission>
        <transmission name="${tf_prefix}_wrist_1_transmission">
            <type>transmission_interface/SimpleTransmission</type>
            <joint name="${tf_prefix}_wrist_1_joint">
            <hardwareInterface>hardware_interface/VelocityJointInterface</hardwareInterface>
            </joint>
            <actuator name="${tf_prefix}_wrist_1_motor">
            <mechanicalReduction>1</mechanicalReduction>
            </actuator>
        </transmission>
        <transmission name="${tf_prefix}_wrist_2_transmission">
            <type>transmission_interface/SimpleTransmission</type>
            <joint name="${tf_prefix}_wrist_2_joint">
            <hardwareInterface>hardware_interface/VelocityJointInterface</hardwareInterface>
            </joint>
            <actuator name="${tf_prefix}_wrist_2_motor">
            <mechanicalReduction>1</mechanicalReduction>
            </actuator>
        </transmission>
        <transmission name="${tf_prefix}_wrist_3_transmission">
            <type>transmission_interface/SimpleTransmission</type>
            <joint name="${tf_prefix}_wrist_3_joint">
            <hardwareInterface>hardware_interface/VelocityJointInterface</hardwareInterface>
            </joint>
            <actuator name="${tf_prefix}_wrist_3_motor">
            <mechanicalReduction>1</mechanicalReduction>
            </actuator>
        </transmission>


    </xacro:macro>
    
</robot>